Workbook

Sheet Match Data - T
A1: MatchID | B1: Season | C1: H/V | D1: TeamID | E1: Team Captain | F1: TC All Stars | G1: TC-G1-AS | H1: TC-G2-AS | I1: TC-G3-AS | J1: TC-G4-AS | K1: TC-G5-AS | L1: Partner | M1: P-G1-AS | N1: P-G2-AS | O1: P-G3-AS | P1: P-G4-AS | Q1: P-G5-AS | R1: Partner All Stars | S1: G1 501 Avg | T1: G1 501 Pts | U1: G1 Out Player | V1: Out Score | W1: G2 501 Avg | X1: G2 501 Pts | Y1: G2 Out Player | Z1: G2 Out Score | AA1: 501 Avg | AB1: G3 Crick Avg | AC1: G3 Crick Pts | AD1: G3 Crick Close | AE1: G4 Crick Avg | AF1: G4 Crick Pts | AG1: G4 Crick Close | AH1: Crick Avg | AI1: 301 Avg | AJ1: G5 In Player | AK1: G5 In Score | AL1: G5 Out Player | AM1: G5 Out Score | AN1: 301 Pts | AO1: Tot Points
A2: 1-1 | B2: 2024 Winter | C2: H | D2: Daniel/David | E2: =LEFT(Table1[[#This Row],[TeamID]],FIND("/",Table1[[#This Row],[TeamID]])-1) -> Daniel | F2: 2 | L2: =SUBSTITUTE(Table1[[#This Row],[TeamID]],Table1[[#This Row],[Team Captain]]&"/","") -> David | R2: 1 | S2: 35.4 | T2: 0 | W2: 30.8 | X2: 0 | AA2: =(S2+W2)/2 -> 33.1 | AB2: 1.33 | AC2: 0 | AE2: 1.37 | AF2: 1 | AH2: =(AB2+AE2)/2 -> 1.35 | AI2: 23.76 | AN2: 1 | AO2: =T2+AC2+AN2+AF2+X2 -> 2
A3: 1-1 | B3: 2024 Winter | C3: V | D3: Brian/Olver | E3: =LEFT(Table1[[#This Row],[TeamID]],FIND("/",Table1[[#This Row],[TeamID]])-1) -> Brian | F3: 1 | L3: =SUBSTITUTE(Table1[[#This Row],[TeamID]],Table1[[#This Row],[Team Captain]]&"/","") -> Olver | R3: 1 | S3: 35.7 | T3: 1 | W3: 32.7 | X3: 1 | AA3: =(S3+W3)/2 -> 34.2 | AB3: 1.58 | AC3: 1 | AE3: 1.05 | AF3: 0 | AH3: =(AB3+AE3)/2 -> 1.315 | AI3: 23.42 | AN3: 0 | AO3: =T3+AC3+AN3+AF3+X3 -> 3
A4: 1-2 | B4: 2024 Winter | C4: H | D4: Tayven/Tony | E4: =LEFT(Table1[[#This Row],[TeamID]],FIND("/",Table1[[#This Row],[TeamID]])-1) -> Tayven | F4: 0 | L4: =SUBSTITUTE(Table1[[#This Row],[TeamID]],Table1[[#This Row],[Team Captain]]&"/","") -> Tony | R4: 0 | S4: 36.08 | T4: 0 | W4: 35.46 | X4: 0 | AA4: =(S4+W4)/2 -> 35.77 | AB4: 0.96 | AC4: 0 | AE4: 1.04 | AF4: 1 | AH4: =(AB4+AE4)/2 -> 1 | AI4: 22.68 | AN4: 0 | AO4: =T4+AC4+AN4+AF4+X4 -> 1
A5: 1-2 | B5: 2024 Winter | C5: V | D5: Mark/Neil | E5: =LEFT(Table1[[#This Row],[TeamID]],FIND("/",Table1[[#This Row],[TeamID]])-1) -> Mark | F5: 3 | L5: =SUBSTITUTE(Table1[[#This Row],[TeamID]],Table1[[#This Row],[Team Captain]]&"/","") -> Neil | R5: 1 | S5: 39.55 | T5: 1 | W5: 36.66 | X5: 1 | AA5: =(S5+W5)/2 -> 38.105 | AB5: 1.09 | AC5: 1 | AE5: 1.04 | AF5: 0 | AH5: =(AB5+AE5)/2 -> 1.065 | AI5: 27.76 | AN5: 1 | AO5: =T5+AC5+AN5+AF5+X5 -> 4
A6: 1-3 | B6: 2024 Winter | C6: H | D6: Clarence/Mike H | E6: =LEFT(Table1[[#This Row],[TeamID]],FIND("/",Table1[[#This Row],[TeamID]])-1) -> Clarence | F6: 0 | L6: =SUBSTITUTE(Table1[[#This Row],[TeamID]],Table1[[#This Row],[Team Captain]]&"/","") -> Mike H | R6: 0 | S6: 40.62 | T6: 1 | W6: 32.5 | X6: 0 | AA6: =(S6+W6)/2 -> 36.56 | AB6: 0.98 | AC6: 1 | AE6: 1.24 | AF6: 0 | AH6: =(AB6+AE6)/2 -> 1.11 | AI6: 22.77 | AN6: 0 | AO6: =T6+AC6+AN6+AF6+X6 -> 2
A7: 1-3 | B7: 2024 Winter | C7: V | D7: Todd/Mike C | E7: =LEFT(Table1[[#This Row],[TeamID]],FIND("/",Table1[[#This Row],[TeamID]])-1) -> Todd | F7: 1 | L7: =SUBSTITUTE(Table1[[#This Row],[TeamID]],Table1[[#This Row],[Team Captain]]&"/","") -> Mike C | R7: 0 | S7: 40.83 | T7: 0 | W7: 39.55 | X7: 1 | AA7: =(S7+W7)/2 -> 40.19 | AB7: 0.69 | AC7: 0 | AE7: 1.33 | AF7: 1 | AH7: =(AB7+AE7)/2 -> 1.01 | AI7: 23.76 | AN7: 1 | AO7: =T7+AC7+AN7+AF7+X7 -> 3
A8: 1-4 | B8: 2024 Winter | C8: H | D8: Kevin/Paul | E8: =LEFT(Table1[[#This Row],[TeamID]],FIND("/",Table1[[#This Row],[TeamID]])-1) -> Kevin | F8: 1 | I8: 1 | L8: =SUBSTITUTE(Table1[[#This Row],[TeamID]],Table1[[#This Row],[Team Captain]]&"/","") -> Paul | R8: 0 | S8: 32.7 | T8: 1 | U8: Kevin | V8: 20 | W8: 39.1 | X8: 0 | AA8: =(S8+W8)/2 -> 35.9 | AB8: 1.3 | AC8: 0 | AE8: 1.5 | AF8: 1 | AH8: =(AB8+AE8)/2 -> 1.4 | AI8: 11 | AJ8: Kevin | AK8: 35 | AN8: 0 | AO8: =T8+AC8+AN8+AF8+X8 -> 2
A9: 1-4 | B9: 2024 Winter | C9: V | D9: Jason/Mike A | E9: =LEFT(Table1[[#This Row],[TeamID]],FIND("/",Table1[[#This Row],[TeamID]])-1) -> Jason | F9: 1 | J9: 1 | L9: =SUBSTITUTE(Table1[[#This Row],[TeamID]],Table1[[#This Row],[Team Captain]]&"/","") -> Mike A | M9: 1 | R9: 1 | S9: 31.8 | T9: 0 | W9: 39.6 | X9: 1 | Y9: Mike A | Z9: 24 | AA9: =(S9+W9)/2 -> 35.7 | AB9: 1.3 | AC9: 1 | AE9: 1.5 | AF9: 0 | AH9: =(AB9+AE9)/2 -> 1.4 | AI9: 10.8 | AJ9: Mike A | AK9: 20 | AL9: Mike A | AM9: 4 | AN9: 1 | AO9: =T9+AC9+AN9+AF9+X9 -> 3
A10: 2-1 | B10: 2024 Winter | C10: H | D10: Jason/Mike A | E10: =LEFT(Table1[[#This Row],[TeamID]],FIND("/",Table1[[#This Row],[TeamID]])-1) -> Jason | F10: 1 | L10: =SUBSTITUTE(Table1[[#This Row],[TeamID]],Table1[[#This Row],[Team Captain]]&"/","") -> Mike A | R10: 1 | S10: 39.55 | T10: 1 | W10: 20.04 | X10: 1 | AA10: =(S10+W10)/2 -> 29.795 | AB10: 0.93 | AC10: 1 | AE10: 1.12 | AF10: 0 | AH10: =(AB10+AE10)/2 -> 1.025 | AI10: 39.26 | AN10: 1 | AO10: =T10+AC10+AN10+AF10+X10 -> 4
A11: 2-1 | B11: 2024 Winter | C11: V | D11: Todd/Mike C | E11: =LEFT(Table1[[#This Row],[TeamID]],FIND("/",Table1[[#This Row],[TeamID]])-1) -> Todd | F11: 0 | L11: =SUBSTITUTE(Table1[[#This Row],[TeamID]],Table1[[#This Row],[Team Captain]]&"/","") -> Mike C | R11: 0 | S11: 36.23 | T11: 0 | W11: 20.79 | X11: 0 | AA11: =(S11+W11)/2 -> 28.51 | AB11: 0.88 | AC11: 0 | AE11: 1.76 | AF11: 1 | AH11: =(AB11+AE11)/2 -> 1.32 | AI11: 39.86 | AN11: 0 | AO11: =T11+AC11+AN11+AF11+X11 -> 1
A12: 2-2 | B12: 2024 Winter | C12: H | D12: Kevin/Paul | E12: =LEFT(Table1[[#This Row],[TeamID]],FIND("/",Table1[[#This Row],[TeamID]])-1) -> Kevin | F12: 1 | L12: =SUBSTITUTE(Table1[[#This Row],[TeamID]],Table1[[#This Row],[Team Captain]]&"/","") -> Paul | R12: 1 | S12: 34.6 | T12: 0 | W12: 47 | X12: 1 | AA12: =(S12+W12)/2 -> 40.8 | AB12: 1.15 | AC12: 0 | AE12: 1.67 | AF12: 1 | AH12: =(AB12+AE12)/2 -> 1.41 | AI12: 21.8 | AN12: 0 | AO12: =T12+AC12+AN12+AF12+X12 -> 2
A13: 2-2 | B13: 2024 Winter | C13: V | D13: Clarence/Mike H | E13: =LEFT(Table1[[#This Row],[TeamID]],FIND("/",Table1[[#This Row],[TeamID]])-1) -> Clarence | F13: 0 | L13: =SUBSTITUTE(Table1[[#This Row],[TeamID]],Table1[[#This Row],[Team Captain]]&"/","") -> Mike H | R13: 1 | S13: 33.4 | T13: 1 | W13: 43.3 | X13: 0 | AA13: =(S13+W13)/2 -> 38.35 | AB13: 1.19 | AC13: 1 | AE13: 1.27 | AF13: 0 | AH13: =(AB13+AE13)/2 -> 1.23 | AI13: 23.8 | AN13: 1 | AO13: =T13+AC13+AN13+AF13+X13 -> 3
A14: 2-3 | B14: 2024 Winter | C14: H | D14: Daniel/David | E14: =LEFT(Table1[[#This Row],[TeamID]],FIND("/",Table1[[#This Row],[TeamID]])-1) -> Daniel | F14: 2 | L14: =SUBSTITUTE(Table1[[#This Row],[TeamID]],Table1[[#This Row],[Team Captain]]&"/","") -> David | R14: 1 | S14: 41.6 | T14: 0 | W14: 38.5 | X14: 1 | AA14: =(S14+W14)/2 -> 40.05 | AB14: 1.16 | AC14: 1 | AE14: 1.42 | AF14: 1 | AH14: =(AB14+AE14)/2 -> 1.29 | AI14: 29.3 | AN14: 0 | AO14: =T14+AC14+AN14+AF14+X14 -> 3
A15: 2-3 | B15: 2024 Winter | C15: V | D15: Tayven/Tony | E15: =LEFT(Table1[[#This Row],[TeamID]],FIND("/",Table1[[#This Row],[TeamID]])-1) -> Tayven | F15: 0 | L15: =SUBSTITUTE(Table1[[#This Row],[TeamID]],Table1[[#This Row],[Team Captain]]&"/","") -> Tony | R15: 1 | S15: 46.8 | T15: 1 | W15: 44.3 | X15: 0 | AA15: =(S15+W15)/2 -> 45.55 | AB15: 1.12 | AC15: 0 | AE15: 1.25 | AF15: 0 | AH15: =(AB15+AE15)/2 -> 1.185 | AI15: 29.1 | AN15: 1 | AO15: =T15+AC15+AN15+AF15+X15 -> 2
A16: 2-4 | B16: 2024 Winter | C16: H | D16: Brian/Olver | E16: =LEFT(Table1[[#This Row],[TeamID]],FIND("/",Table1[[#This Row],[TeamID]])-1) -> Brian | F16: 0 | L16: =SUBSTITUTE(Table1[[#This Row],[TeamID]],Table1[[#This Row],[Team Captain]]&"/","") -> Olver | R16: 0 | S16: 32.6 | T16: 0 | W16: 43.1 | X16: 0 | AA16: =(S16+W16)/2 -> 37.85 | AB16: 1.42 | AC16: 0 | AE16: 0.73 | AF16: 0 | AH16: =(AB16+AE16)/2 -> 1.075 | AI16: 17.4 | AN16: 1 | AO16: =T16+AC16+AN16+AF16+X16 -> 1
A17: 2-4 | B17: 2024 Winter | C17: V | D17: Mark/Neil | E17: =LEFT(Table1[[#This Row],[TeamID]],FIND("/",Table1[[#This Row],[TeamID]])-1) -> Mark | F17: 2 | L17: =SUBSTITUTE(Table1[[#This Row],[TeamID]],Table1[[#This Row],[Team Captain]]&"/","") -> Neil | R17: 1 | S17: 37.6 | T17: 1 | W17: 48.5 | X17: 1 | AA17: =(S17+W17)/2 -> 43.05 | AB17: 1.6 | AC17: 1 | AE17: 0.93 | AF17: 1 | AH17: =(AB17+AE17)/2 -> 1.265 | AI17: 16.3 | AN17: 0 | AO17: =T17+AC17+AN17+AF17+X17 -> 4
A18: 3-1 | B18: 2024 Winter | C18: H | D18: Tayven/Tony | E18: =LEFT(Table1[[#This Row],[TeamID]],FIND("/",Table1[[#This Row],[TeamID]])-1) -> Tayven | F18: 4 | L18: =SUBSTITUTE(Table1[[#This Row],[TeamID]],Table1[[#This Row],[Team Captain]]&"/","") -> Tony | R18: 0 | S18: 34.95 | T18: 1 | W18: 36.66 | X18: 1 | AA18: =(S18+W18)/2 -> 35.805 | AB18: 1.06 | AC18: 0 | AE18: 1.27 | AF18: 1 | AH18: =(AB18+AE18)/2 -> 1.165 | AI18: 13.5 | AN18: 0 | AO18: =T18+AC18+AN18+AF18+X18 -> 3
A19: 3-1 | B19: 2024 Winter | C19: V | D19: Clarence/Mike H | E19: =LEFT(Table1[[#This Row],[TeamID]],FIND("/",Table1[[#This Row],[TeamID]])-1) -> Clarence | F19: 1 | L19: =SUBSTITUTE(Table1[[#This Row],[TeamID]],Table1[[#This Row],[Team Captain]]&"/","") -> Mike H | R19: 1 | S19: 25.5 | T19: 0 | W19: 35.5 | X19: 0 | AA19: =(S19+W19)/2 -> 30.5 | AB19: 1.21 | AC19: 1 | AE19: 1 | AF19: 0 | AH19: =(AB19+AE19)/2 -> 1.105 | AI19: 13.18 | AN19: 1 | AO19: =T19+AC19+AN19+AF19+X19 -> 2
A20: 3-2 | B20: 2024 Winter | C20: H | D20: Jason/Mike A | E20: =LEFT(Table1[[#This Row],[TeamID]],FIND("/",Table1[[#This Row],[TeamID]])-1) -> Jason | F20: 1 | L20: =SUBSTITUTE(Table1[[#This Row],[TeamID]],Table1[[#This Row],[Team Captain]]&"/","") -> Mike A | R20: 1 | S20: 32.7 | T20: 1 | W20: 50.1 | X20: 1 | AA20: =(S20+W20)/2 -> 41.4 | AB20: 1.45 | AC20: 1 | AE20: 1.5 | AF20: 1 | AH20: =(AB20+AE20)/2 -> 1.475 | AI20: 29.9 | AN20: 0 | AO20: =T20+AC20+AN20+AF20+X20 -> 4
A21: 3-2 | B21: 2024 Winter | C21: V | D21: Brian/Olver | E21: =LEFT(Table1[[#This Row],[TeamID]],FIND("/",Table1[[#This Row],[TeamID]])-1) -> Brian | F21: 2 | L21: =SUBSTITUTE(Table1[[#This Row],[TeamID]],Table1[[#This Row],[Team Captain]]&"/","") -> Olver | R21: 1 | S21: 30.31 | T21: 0 | W21: 43.8 | X21: 0 | AA21: =(S21+W21)/2 -> 37.055 | AB21: 0.86 | AC21: 0 | AE21: 1.39 | AF21: 0 | AH21: =(AB21+AE21)/2 -> 1.125 | AI21: 28.22 | AN21: 1 | AO21: =T21+AC21+AN21+AF21+X21 -> 1
... A57: 7-4 | B57: 2024 Winter | C57: V | D57: Tayven/Tony | E57: =LEFT(Table1[[#This Row],[TeamID]],FIND("/",Table1[[#This Row],[TeamID]])-1) -> Tayven | F57: 3 | L57: =SUBSTITUTE(Table1[[#This Row],[TeamID]],Table1[[#This Row],[Team Captain]]&"/","") -> Tony | R57: 1 | S57: 20.75 | T57: 0 | W57: 18.11 | X57: 1 | AA57: =(S57+W57)/2 -> 19.43 | AB57: 1 | AC57: 1 | AE57: 1.81 | AF57: 1 | AH57: =(AB57+AE57)/2 -> 1.405 | AI57: 22.23 | AN57: 0 | AO57: =T57+AC57+AN57+AF57+X57 -> 3
A58: 1-1 | B58: 2024 Summer | C58: H | D58: Mark/Mike C | E58: =LEFT(Table1[[#This Row],[TeamID]],FIND("/",Table1[[#This Row],[TeamID]])-1) -> Mark | F58: =Table1[[#This Row],[TC-G1-AS]]+Table1[[#This Row],[TC-G2-AS]]+Table1[[#This Row],[TC-G3-AS]]+Table1[[#This Row],[TC-G4-AS]]+Table1[[#This Row],[TC-G5-AS]] -> 2 | H58: 1 | J58: 1 | L58: =SUBSTITUTE(Table1[[#This Row],[TeamID]],Table1[[#This Row],[Team Captain]]&"/","") -> Mike C | M58: 2 | R58: =Table1[[#This Row],[P-G1-AS]]+Table1[[#This Row],[P-G2-AS]]+Table1[[#This Row],[P-G3-AS]]+Table1[[#This Row],[P-G4-AS]]+Table1[[#This Row],[P-G5-AS]] -> 2 | S58: 44.27 | T58: 0 | W58: 29.47 | X58: 0 | AA58: =(S58+W58)/2 -> 36.87 | AB58: 1.53 | AC58: 0 | AE58: 1.28 | AF58: 0 | AH58: =(AB58+AE58)/2 -> 1.405 | AI58: 26.27 | AJ58: Mike C | AK58: 39 | AN58: 0 | AO58: =T58+AC58+AN58+AF58+X58 -> 0
A59: 1-1 | B59: 2024 Summer | C59: V | D59: Tayven/Clarence | E59: =LEFT(Table1[[#This Row],[TeamID]],FIND("/",Table1[[#This Row],[TeamID]])-1) -> Tayven | F59: =Table1[[#This Row],[TC-G1-AS]]+Table1[[#This Row],[TC-G2-AS]]+Table1[[#This Row],[TC-G3-AS]]+Table1[[#This Row],[TC-G4-AS]]+Table1[[#This Row],[TC-G5-AS]] -> 1 | K59: 1 | L59: =SUBSTITUTE(Table1[[#This Row],[TeamID]],Table1[[#This Row],[Team Captain]]&"/","") -> Clarence | R59: =Table1[[#This Row],[P-G1-AS]]+Table1[[#This Row],[P-G2-AS]]+Table1[[#This Row],[P-G3-AS]]+Table1[[#This Row],[P-G4-AS]]+Table1[[#This Row],[P-G5-AS]] -> 0 | S59: 44.21 | T59: 1 | U59: Tayven | V59: 14 | W59: 29 | X59: 1 | Y59: Tayven | Z59: 2 | AA59: =(S59+W59)/2 -> 36.605 | AB59: 1.83 | AC59: 1 | AE59: 1.44 | AF59: 1 | AH59: =(AB59+AE59)/2 -> 1.635 | AI59: 26.56 | AJ59: Clarence | AK59: 39 | AL59: Clarence | AM59: 16 | AN59: 1 | AO59: =T59+AC59+AN59+AF59+X59 -> 5
A60: 1-2 | B60: 2024 Summer | C60: H | D60: Daniel/Matt | E60: =LEFT(Table1[[#This Row],[TeamID]],FIND("/",Table1[[#This Row],[TeamID]])-1) -> Daniel | F60: =Table1[[#This Row],[TC-G1-AS]]+Table1[[#This Row],[TC-G2-AS]]+Table1[[#This Row],[TC-G3-AS]]+Table1[[#This Row],[TC-G4-AS]]+Table1[[#This Row],[TC-G5-AS]] -> 1 | J60: 1 | L60: =SUBSTITUTE(Table1[[#This Row],[TeamID]],Table1[[#This Row],[Team Captain]]&"/","") -> Matt | M60: 2 | R60: =Table1[[#This Row],[P-G1-AS]]+Table1[[#This Row],[P-G2-AS]]+Table1[[#This Row],[P-G3-AS]]+Table1[[#This Row],[P-G4-AS]]+Table1[[#This Row],[P-G5-AS]] -> 2 | S60: 41.08 | T60: 0 | W60: 40.08 | X60: 0 | AA60: =(S60+W60)/2 -> 40.58 | AB60: 1.32 | AC60: 0 | AE60: 1.4 | AF60: 1 | AH60: =(AB60+AE60)/2 -> 1.36 | AI60: 27.36 | AJ60: Daniel | AK60: 2 | AL60: Daniel | AM60: 40 | AN60: 1 | AO60: =T60+AC60+AN60+AF60+X60 -> 2
A61: 1-2 | B61: 2024 Summer | C61: V | D61: Todd/Mike H | E61: =LEFT(Table1[[#This Row],[TeamID]],FIND("/",Table1[[#This Row],[TeamID]])-1) -> Todd | F61: =Table1[[#This Row],[TC-G1-AS]]+Table1[[#This Row],[TC-G2-AS]]+Table1[[#This Row],[TC-G3-AS]]+Table1[[#This Row],[TC-G4-AS]]+Table1[[#This Row],[TC-G5-AS]] -> 0 | L61: =SUBSTITUTE(Table1[[#This Row],[TeamID]],Table1[[#This Row],[Team Captain]]&"/","") -> Mike H | R61: =Table1[[#This Row],[P-G1-AS]]+Table1[[#This Row],[P-G2-AS]]+Table1[[#This Row],[P-G3-AS]]+Table1[[#This Row],[P-G4-AS]]+Table1[[#This Row],[P-G5-AS]] -> 0 | S61: 42.94 | T61: 1 | U61: Mike H | V61: 11 | W61: 40.62 | X61: 1 | Y61: Mike H | Z61: 16 | AA61: =(S61+W61)/2 -> 41.78 | AB61: 1.75 | AC61: 1 | AE61: 1.07 | AF61: 0 | AH61: =(AB61+AE61)/2 -> 1.41 | AI61: 29.5 | AJ61: Todd | AK61: 31 | AN61: 0 | AO61: =T61+AC61+AN61+AF61+X61 -> 3
A62: 1-3 | B62: 2024 Summer | C62: H | D62: Mike A/Paul | E62: =LEFT(Table1[[#This Row],[TeamID]],FIND("/",Table1[[#This Row],[TeamID]])-1) -> Mike A | F62: =Table1[[#This Row],[TC-G1-AS]]+Table1[[#This Row],[TC-G2-AS]]+Table1[[#This Row],[TC-G3-AS]]+Table1[[#This Row],[TC-G4-AS]]+Table1[[#This Row],[TC-G5-AS]] -> 0 | L62: =SUBSTITUTE(Table1[[#This Row],[TeamID]],Table1[[#This Row],[Team Captain]]&"/","") -> Paul | O62: 1 | R62: =Table1[[#This Row],[P-G1-AS]]+Table1[[#This Row],[P-G2-AS]]+Table1[[#This Row],[P-G3-AS]]+Table1[[#This Row],[P-G4-AS]]+Table1[[#This Row],[P-G5-AS]] -> 1 | S62: 40.58 | T62: 0 | W62: 41.5 | X62: 0 | AA62: =(S62+W62)/2 -> 41.04 | AB62: 1.37 | AC62: 1 | AE62: 0.95 | AF62: 0 | AH62: =(AB62+AE62)/2 -> 1.16 | AI62: 18.06 | AJ62: Paul | AK62: 44 | AL62: Mike A | AM62: 3 | AN62: 1 | AO62: =T62+AC62+AN62+AF62+X62 -> 2
A63: 1-3 | B63: 2024 Summer | C63: V | D63: Brian/Neil | E63: =LEFT(Table1[[#This Row],[TeamID]],FIND("/",Table1[[#This Row],[TeamID]])-1) -> Brian | F63: =Table1[[#This Row],[TC-G1-AS]]+Table1[[#This Row],[TC-G2-AS]]+Table1[[#This Row],[TC-G3-AS]]+Table1[[#This Row],[TC-G4-AS]]+Table1[[#This Row],[TC-G5-AS]] -> 2 | I63: 1 | J63: 1 | L63: =SUBSTITUTE(Table1[[#This Row],[TeamID]],Table1[[#This Row],[Team Captain]]&"/","") -> Neil | R63: =Table1[[#This Row],[P-G1-AS]]+Table1[[#This Row],[P-G2-AS]]+Table1[[#This Row],[P-G3-AS]]+Table1[[#This Row],[P-G4-AS]]+Table1[[#This Row],[P-G5-AS]] -> 0 | S63: 39.55 | T63: 1 | U63: Brian | V63: 16 | W63: 44.21 | X63: 1 | Y63: Brian | Z63: 32 | AA63: =(S63+W63)/2 -> 41.88 | AB63: 1.21 | AC63: 0 | AE63: 1.18 | AF63: 1 | AH63: =(AB63+AE63)/2 -> 1.195 | AI63: 17.35 | AJ63: Neil | AK63: 50 | AN63: 0 | AO63: =T63+AC63+AN63+AF63+X63 -> 3
A64: 1-4 | B64: 2024 Summer | C64: H | D64: Jason/Olver | E64: =LEFT(Table1[[#This Row],[TeamID]],FIND("/",Table1[[#This Row],[TeamID]])-1) -> Jason | F64: =Table1[[#This Row],[TC-G1-AS]]+Table1[[#This Row],[TC-G2-AS]]+Table1[[#This Row],[TC-G3-AS]]+Table1[[#This Row],[TC-G4-AS]]+Table1[[#This Row],[TC-G5-AS]] -> 2 | J64: 2 | L64: =SUBSTITUTE(Table1[[#This Row],[TeamID]],Table1[[#This Row],[Team Captain]]&"/","") -> Olver | R64: =Table1[[#This Row],[P-G1-AS]]+Table1[[#This Row],[P-G2-AS]]+Table1[[#This Row],[P-G3-AS]]+Table1[[#This Row],[P-G4-AS]]+Table1[[#This Row],[P-G5-AS]] -> 0 | S64: 33.78 | T64: 0 | W64: 35.36 | X64: 0 | AA64: =(S64+W64)/2 -> 34.57 | AB64: 0.78 | AC64: 0 | AE64: 1.45 | AF64: 0 | AH64: =(AB64+AE64)/2 -> 1.115 | AI64: 19.93 | AJ64: Jason | AK64: 52 | AN64: 0 | AO64: =T64+AC64+AN64+AF64+X64 -> 0
A65: 1-4 | B65: 2024 Summer | C65: V | D65: Kevin/Tony | E65: =LEFT(Table1[[#This Row],[TeamID]],FIND("/",Table1[[#This Row],[TeamID]])-1) -> Kevin | F65: =Table1[[#This Row],[TC-G1-AS]]+Table1[[#This Row],[TC-G2-AS]]+Table1[[#This Row],[TC-G3-AS]]+Table1[[#This Row],[TC-G4-AS]]+Table1[[#This Row],[TC-G5-AS]] -> 2 | G65: 1 | H65: 1 | L65: =SUBSTITUTE(Table1[[#This Row],[TeamID]],Table1[[#This Row],[Team Captain]]&"/","") -> Tony | N65: 1 | R65: =Table1[[#This Row],[P-G1-AS]]+Table1[[#This Row],[P-G2-AS]]+Table1[[#This Row],[P-G3-AS]]+Table1[[#This Row],[P-G4-AS]]+Table1[[#This Row],[P-G5-AS]] -> 1 | S65: 50.01 | T65: 1 | U65: Tony | V65: 72 | W65: 35.79 | X65: 1 | Y65: Kevin | Z65: 32 | AA65: =(S65+W65)/2 -> 42.9 | AB65: 1.26 | AC65: 1 | AE65: 1.33 | AF65: 1 | AH65: =(AB65+AE65)/2 -> 1.295 | AI65: 20.07 | AJ65: Kevin | AK65: 32 | AL65: Kevin | AM65: 8 | AN65: 1 | AO65: =T65+AC65+AN65+AF65+X65 -> 5
A66: 2-1 | B66: 2024 Summer | C66: H | D66: Kevin/Tony | E66: =LEFT(Table1[[#This Row],[TeamID]],FIND("/",Table1[[#This Row],[TeamID]])-1) -> Kevin | F66: =Table1[[#This Row],[TC-G1-AS]]+Table1[[#This Row],[TC-G2-AS]]+Table1[[#This Row],[TC-G3-AS]]+Table1[[#This Row],[TC-G4-AS]]+Table1[[#This Row],[TC-G5-AS]] -> 2 | I66: 1 | K66: 1 | L66: =SUBSTITUTE(Table1[[#This Row],[TeamID]],Table1[[#This Row],[Team Captain]]&"/","") -> Tony | M66: 1 | R66: =Table1[[#This Row],[P-G1-AS]]+Table1[[#This Row],[P-G2-AS]]+Table1[[#This Row],[P-G3-AS]]+Table1[[#This Row],[P-G4-AS]]+Table1[[#This Row],[P-G5-AS]] -> 1 | S66: 35.07 | T66: 0 | W66: 25.91 | X66: 1 | Y66: Kevin | Z66: 8 | AA66: =(S66+W66)/2 -> 30.49 | AB66: 1.4 | AC66: 0 | AE66: 1.05 | AF66: 0 | AH66: =(AB66+AE66)/2 -> 1.225 | AI66: 64.5 | AJ66: Kevin | AK66: 54 | AL66: Kevin | AM66: 48 | AN66: 1 | AO66: =T66+AC66+AN66+AF66+X66 -> 2
A67: 2-1 | B67: 2024 Summer | C67: V | D67: Brian/Neil | E67: =LEFT(Table1[[#This Row],[TeamID]],FIND("/",Table1[[#This Row],[TeamID]])-1) -> Brian | F67: =Table1[[#This Row],[TC-G1-AS]]+Table1[[#This Row],[TC-G2-AS]]+Table1[[#This Row],[TC-G3-AS]]+Table1[[#This Row],[TC-G4-AS]]+Table1[[#This Row],[TC-G5-AS]] -> 1 | J67: 1 | L67: =SUBSTITUTE(Table1[[#This Row],[TeamID]],Table1[[#This Row],[Team Captain]]&"/","") -> Neil | R67: =Table1[[#This Row],[P-G1-AS]]+Table1[[#This Row],[P-G2-AS]]+Table1[[#This Row],[P-G3-AS]]+Table1[[#This Row],[P-G4-AS]]+Table1[[#This Row],[P-G5-AS]] -> 0 | S67: 33.4 | T67: 1 | U67: Brian | V67: 32 | W67: 25.84 | AA67: =(S67+W67)/2 -> 29.62 | AB67: 1.44 | AC67: 1 | AE67: 1.1 | AF67: 1 | AH67: =(AB67+AE67)/2 -> 1.27 | AI67: 25.8 | AJ67: Brian | AK67: 34 | AO67: =T67+AC67+AN67+AF67+X67 -> 3
A68: 2-2 | B68: 2024 Summer | C68: H | D68: Daniel/Matt | E68: =LEFT(Table1[[#This Row],[TeamID]],FIND("/",Table1[[#This Row],[TeamID]])-1) -> Daniel | F68: =Table1[[#This Row],[TC-G1-AS]]+Table1[[#This Row],[TC-G2-AS]]+Table1[[#This Row],[TC-G3-AS]]+Table1[[#This Row],[TC-G4-AS]]+Table1[[#This Row],[TC-G5-AS]] -> 1 | H68: 1 | L68: =SUBSTITUTE(Table1[[#This Row],[TeamID]],Table1[[#This Row],[Team Captain]]&"/","") -> Matt | R68: =Table1[[#This Row],[P-G1-AS]]+Table1[[#This Row],[P-G2-AS]]+Table1[[#This Row],[P-G3-AS]]+Table1[[#This Row],[P-G4-AS]]+Table1[[#This Row],[P-G5-AS]] -> 0 | S68: 33.4 | T68: 1 | U68: Daniel | V68: 33 | W68: 37.57 | X68: 1 | Y68: Daniel | Z68: 20 | AA68: =(S68+W68)/2 -> 35.485 | AB68: 1.57 | AC68: 1 | AE68: 1.62 | AF68: 1 | AH68: =(AB68+AE68)/2 -> 1.595 | AI68: 30.1 | AJ68: Daniel | AK68: 70 | AL68: Daniel | AM68: 68 | AN68: 1 | AO68: =T68+AC68+AN68+AF68+X68 -> 5
A69: 2-2 | B69: 2024 Summer | C69: V | D69: Mark/Mike C | E69: =LEFT(Table1[[#This Row],[TeamID]],FIND("/",Table1[[#This Row],[TeamID]])-1) -> Mark | F69: =Table1[[#This Row],[TC-G1-AS]]+Table1[[#This Row],[TC-G2-AS]]+Table1[[#This Row],[TC-G3-AS]]+Table1[[#This Row],[TC-G4-AS]]+Table1[[#This Row],[TC-G5-AS]] -> 1 | J69: 1 | L69: =SUBSTITUTE(Table1[[#This Row],[TeamID]],Table1[[#This Row],[Team Captain]]&"/","") -> Mike C | R69: =Table1[[#This Row],[P-G1-AS]]+Table1[[#This Row],[P-G2-AS]]+Table1[[#This Row],[P-G3-AS]]+Table1[[#This Row],[P-G4-AS]]+Table1[[#This Row],[P-G5-AS]] -> 0 | S69: 34.64 | T69: 0 | W69: 32.25 | X69: 0 | AA69: =(S69+W69)/2 -> 33.445 | AB69: 1.14 | AC69: 0 | AE69: 1.4 | AF69: 0 | AH69: =(AB69+AE69)/2 -> 1.27 | AI69: 29.56 | AJ69: Mark | AK69: 42 | AN69: 0 | AO69: =T69+AC69+AN69+AF69+X69 -> 0
A70: 2-3 | B70: 2024 Summer | C70: H | D70: Todd/Mike H | E70: =LEFT(Table1[[#This Row],[TeamID]],FIND("/",Table1[[#This Row],[TeamID]])-1) -> Todd | F70: =Table1[[#This Row],[TC-G1-AS]]+Table1[[#This Row],[TC-G2-AS]]+Table1[[#This Row],[TC-G3-AS]]+Table1[[#This Row],[TC-G4-AS]]+Table1[[#This Row],[TC-G5-AS]] -> 1 | I70: 1 | L70: =SUBSTITUTE(Table1[[#This Row],[TeamID]],Table1[[#This Row],[Team Captain]]&"/","") -> Mike H | R70: =Table1[[#This Row],[P-G1-AS]]+Table1[[#This Row],[P-G2-AS]]+Table1[[#This Row],[P-G3-AS]]+Table1[[#This Row],[P-G4-AS]]+Table1[[#This Row],[P-G5-AS]] -> 0 | S70: 33 | T70: 0 | W70: 29 | X70: 0 | AA70: =(S70+W70)/2 -> 31 | AB70: 1.33 | AC70: 1 | AE70: 1.45 | AF70: 1 | AH70: =(AB70+AE70)/2 -> 1.39 | AI70: 28.22 | AJ70: Todd | AK70: 22 | AL70: Mike H | AM70: 8 | AN70: 1 | AO70: =T70+AC70+AN70+AF70+X70 -> 3
A71: 2-3 | B71: 2024 Summer | C71: V | D71: Tayven/Clarence | E71: =LEFT(Table1[[#This Row],[TeamID]],FIND("/",Table1[[#This Row],[TeamID]])-1) -> Tayven | F71: =Table1[[#This Row],[TC-G1-AS]]+Table1[[#This Row],[TC-G2-AS]]+Table1[[#This Row],[TC-G3-AS]]+Table1[[#This Row],[TC-G4-AS]]+Table1[[#This Row],[TC-G5-AS]] -> 4 | G71: 1 | I71: 1 | K71: 2 | L71: =SUBSTITUTE(Table1[[#This Row],[TeamID]],Table1[[#This Row],[Team Captain]]&"/","") -> Clarence | R71: =Table1[[#This Row],[P-G1-AS]]+Table1[[#This Row],[P-G2-AS]]+Table1[[#This Row],[P-G3-AS]]+Table1[[#This Row],[P-G4-AS]]+Table1[[#This Row],[P-G5-AS]] -> 0 | S71: 36.66 | T71: 1 | U71: Tayven | V71: 4 | W71: 33.4 | X71: 1 | Y71: Tayven | Z71: 2 | AA71: =(S71+W71)/2 -> 35.03 | AB71: 1.3 | AC71: 0 | AE71: 1.35 | AF71: 0 | AH71: =(AB71+AE71)/2 -> 1.325 | AI71: 27.2 | AJ71: Tayven | AK71: 108 | AN71: 0 | AO71: =T71+AC71+AN71+AF71+X71 -> 2
A72: 2-4 | B72: 2024 Summer | C72: H | D72: Jason/Olver | E72: =LEFT(Table1[[#This Row],[TeamID]],FIND("/",Table1[[#This Row],[TeamID]])-1) -> Jason | F72: =Table1[[#This Row],[TC-G1-AS]]+Table1[[#This Row],[TC-G2-AS]]+Table1[[#This Row],[TC-G3-AS]]+Table1[[#This Row],[TC-G4-AS]]+Table1[[#This Row],[TC-G5-AS]] -> 1 | I72: 1 | L72: =SUBSTITUTE(Table1[[#This Row],[TeamID]],Table1[[#This Row],[Team Captain]]&"/","") -> Olver | N72: 1 | R72: =Table1[[#This Row],[P-G1-AS]]+Table1[[#This Row],[P-G2-AS]]+Table1[[#This Row],[P-G3-AS]]+Table1[[#This Row],[P-G4-AS]]+Table1[[#This Row],[P-G5-AS]] -> 1 | S72: 17.48 | T72: 1 | U72: Jason | V72: 2 | W72: 34.95 | X72: 1 | Y72: Olver | Z72: 20 | AA72: =(S72+W72)/2 -> 26.215 | AB72: 0.78 | AC72: 0 | AE72: 0.87 | AF72: 0 | AH72: =(AB72+AE72)/2 -> 0.825 | AI72: 39.26 | AJ72: Jason | AK72: 32 | AL72: Olver | AM72: 20 | AN72: 1 | AO72: =T72+AC72+AN72+AF72+X72 -> 3
A73: 2-4 | B73: 2024 Summer | C73: V | D73: Mike A/Paul | E73: =LEFT(Table1[[#This Row],[TeamID]],FIND("/",Table1[[#This Row],[TeamID]])-1) -> Mike A | F73: =Table1[[#This Row],[TC-G1-AS]]+Table1[[#This Row],[TC-G2-AS]]+Table1[[#This Row],[TC-G3-AS]]+Table1[[#This Row],[TC-G4-AS]]+Table1[[#This Row],[TC-G5-AS]] -> 0 | L73: =SUBSTITUTE(Table1[[#This Row],[TeamID]],Table1[[#This Row],[Team Captain]]&"/","") -> Paul | R73: =Table1[[#This Row],[P-G1-AS]]+Table1[[#This Row],[P-G2-AS]]+Table1[[#This Row],[P-G3-AS]]+Table1[[#This Row],[P-G4-AS]]+Table1[[#This Row],[P-G5-AS]] -> 0 | S73: 17.82 | T73: 0 | W73: 32.87 | X73: 0 | AA73: =(S73+W73)/2 -> 25.345 | AB73: 1.3 | AC73: 1 | AE73: 1.29 | AF73: 1 | AH73: =(AB73+AE73)/2 -> 1.295 | AI73: 34.88 | AJ73: Mike A | AK73: 45 | AN73: 0 | AO73: =T73+AC73+AN73+AF73+X73 -> 2
A74: 3-1 | B74: 2024 Summer | C74: H | D74: Mark/Mike C | E74: =LEFT(Table1[[#This Row],[TeamID]],FIND("/",Table1[[#This Row],[TeamID]])-1) -> Mark | F74: =Table1[[#This Row],[TC-G1-AS]]+Table1[[#This Row],[TC-G2-AS]]+Table1[[#This Row],[TC-G3-AS]]+Table1[[#This Row],[TC-G4-AS]]+Table1[[#This Row],[TC-G5-AS]] -> 0 | L74: =SUBSTITUTE(Table1[[#This Row],[TeamID]],Table1[[#This Row],[Team Captain]]&"/","") -> Mike C | Q74: 1 | R74: =Table1[[#This Row],[P-G1-AS]]+Table1[[#This Row],[P-G2-AS]]+Table1[[#This Row],[P-G3-AS]]+Table1[[#This Row],[P-G4-AS]]+Table1[[#This Row],[P-G5-AS]] -> 1 | S74: 13.42 | T74: 1 | U74: Mike C | V74: 3 | W74: 37.57 | X74: 1 | Y74: Mark | Z74: 3 | AA74: =(S74+W74)/2 -> 25.495 | AB74: 0.96 | AC74: 1 | AE74: 1.5 | AF74: 0 | AH74: =(AB74+AE74)/2 -> 1.23 | AI74: 24.08 | AJ74: Mark | AK74: 19 | AN74: 0 | AO74: =T74+AC74+AN74+AF74+X74 -> 3
A75: 3-1 | B75: 2024 Summer | C75: V | D75: Mike A/Paul | E75: =LEFT(Table1[[#This Row],[TeamID]],FIND("/",Table1[[#This Row],[TeamID]])-1) -> Mike A | F75: =Table1[[#This Row],[TC-G1-AS]]+Table1[[#This Row],[TC-G2-AS]]+Table1[[#This Row],[TC-G3-AS]]+Table1[[#This Row],[TC-G4-AS]]+Table1[[#This Row],[TC-G5-AS]] -> 2 | G75: 1 | K75: 1 | L75: =SUBSTITUTE(Table1[[#This Row],[TeamID]],Table1[[#This Row],[Team Captain]]&"/","") -> Paul | R75: =Table1[[#This Row],[P-G1-AS]]+Table1[[#This Row],[P-G2-AS]]+Table1[[#This Row],[P-G3-AS]]+Table1[[#This Row],[P-G4-AS]]+Table1[[#This Row],[P-G5-AS]] -> 0 | S75: 13.13 | T75: 0 | W75: 35.77 | X75: 0 | AA75: =(S75+W75)/2 -> 24.45 | AB75: 0.96 | AC75: 0 | AE75: 2 | AF75: 1 | AH75: =(AB75+AE75)/2 -> 1.48 | AI75: 23.76 | AJ75: Mike A | AK75: 46 | AL75: Mike A | AM75: 4 | AN75: 1 | AO75: =T75+AC75+AN75+AF75+X75 -> 2
...

Sheet Match Data - D
A1: Games | AG1: Points | AP1: 501 Average | AY1: Cricket Average | BH1: 301 Average
B2: Played | C2: H1 501 Avg | D2: V1 501 Avg | E2: H1 501 Pts | F2: V1 501 Pts | G2: H2 501 Avg | H2: V2 501 Avg | I2: H2 501 Pts | J2: V2 501 Pts | K2: H 501 Avg | L2: V 501 Avg | M2: H1 Crick Avg | N2: V1 Crick Avg | O2: H1 Crick Pts | P2: V1 Crick Pts | Q2: H2 Crick Avg | R2: V2 Crick Avg | S2: H2 Crick Pts | T2: V2 Crick Pts | U2: H Crick Avg | V2: V Crick Avg | W2: H 301 Avg | X2: V 301 Avg | Y2: H 301 Pts | Z2: V 301 Pts | AA2: H Tot Points | AB2: V Tot Points | AD2: Point Check | AG2: ='Team Stats'!$A$2 -> Todd/Mike C | AH2: ='Team Stats'!$A$3 -> Clarence/Mike H | AI2: ='Team Stats'!$A$4 -> Jason/Mike A | AJ2: ='Team Stats'!$A$5 -> Kevin/Paul | AK2: ='Team Stats'!$A$6 -> Mark/Neil | AL2: ='Team Stats'!$A$7 -> Tayven/Tony | AM2: ='Team Stats'!$A$8 -> Brian/Olver | AN2: ='Team Stats'!$A$9 -> Daniel/David | AO2: CHECK | AP2: ='Team Stats'!$A$2 -> Todd/Mike C | AQ2: ='Team Stats'!$A$3 -> Clarence/Mike H | AR2: ='Team Stats'!$A$4 -> Jason/Mike A | AS2: ='Team Stats'!$A$5 -> Kevin/Paul | AT2: ='Team Stats'!$A$6 -> Mark/Neil | AU2: ='Team Stats'!$A$7 -> Tayven/Tony | AV2: ='Team Stats'!$A$8 -> Brian/Olver | AW2: ='Team Stats'!$A$9 -> Daniel/David | AY2: ='Team Stats'!$A$2 -> Todd/Mike C | AZ2: ='Team Stats'!$A$3 -> Clarence/Mike H | BA2: ='Team Stats'!$A$4 -> Jason/Mike A | BB2: ='Team Stats'!$A$5 -> Kevin/Paul | BC2: ='Team Stats'!$A$6 -> Mark/Neil | BD2: ='Team Stats'!$A$7 -> Tayven/Tony | BE2: ='Team Stats'!$A$8 -> Brian/Olver | BF2: ='Team Stats'!$A$9 -> Daniel/David | BH2: ='Team Stats'!$A$2 -> Todd/Mike C | BI2: ='Team Stats'!$A$3 -> Clarence/Mike H | BJ2: ='Team Stats'!$A$4 -> Jason/Mike A | BK2: ='Team Stats'!$A$5 -> Kevin/Paul | BL2: ='Team Stats'!$A$6 -> Mark/Neil | BM2: ='Team Stats'!$A$7 -> Tayven/Tony | BN2: ='Team Stats'!$A$8 -> Brian/Olver | BO2: ='Team Stats'!$A$9 -> Daniel/David
A3: Daniel/David | B3: Brian/Olver | C3: 35.4 | D3: 35.7 | E3: 0 | F3: 1 | G3: 30.8 | H3: 32.7 | I3: 0 | J3: 1 | K3: =(C3+G3)/2 -> 33.1 | L3: =(D3+H3)/2 -> 34.2 | M3: 1.33 | N3: 1.58 | O3: 0 | P3: 1 | Q3: 1.37 | R3: 1.05 | S3: 1 | T3: 0 | U3: =(M3+Q3)/2 -> 1.35 | V3: =(N3+R3)/2 -> 1.315 | W3: 23.76 | X3: 23.42 | Y3: 1 | Z3: 0 | AA3: =E3+O3+Y3+S3+I3 -> 2 | AB3: =F3+P3+Z3+J3+T3 -> 3 | AD3: =IF(AA3+AB3 = 5, "Good", "ERROR") -> Good | AG3: =IFERROR(VLOOKUP(AG$2,$A3:$AA3,27,FALSE),0)+IFERROR(VLOOKUP(AG$2,$B3:$AB3,27,FALSE),0) -> 0 | AH3: =IFERROR(VLOOKUP(AH$2,$A3:$AA3,27,FALSE),0)+IFERROR(VLOOKUP(AH$2,$B3:$AB3,27,FALSE),0) -> 0 | AI3: =IFERROR(VLOOKUP(AI$2,$A3:$AA3,27,FALSE),0)+IFERROR(VLOOKUP(AI$2,$B3:$AB3,27,FALSE),0) -> 0 | AJ3: =IFERROR(VLOOKUP(AJ$2,$A3:$AA3,27,FALSE),0)+IFERROR(VLOOKUP(AJ$2,$B3:$AB3,27,FALSE),0) -> 0 | AK3: =IFERROR(VLOOKUP(AK$2,$A3:$AA3,27,FALSE),0)+IFERROR(VLOOKUP(AK$2,$B3:$AB3,27,FALSE),0) -> 0 | AL3: =IFERROR(VLOOKUP(AL$2,$A3:$AA3,27,FALSE),0)+IFERROR(VLOOKUP(AL$2,$B3:$AB3,27,FALSE),0) -> 0 | AM3: =IFERROR(VLOOKUP(AM$2,$A3:$AA3,27,FALSE),0)+IFERROR(VLOOKUP(AM$2,$B3:$AB3,27,FALSE),0) -> 3 | AN3: =IFERROR(VLOOKUP(AN$2,$A3:$AA3,27,FALSE),0)+IFERROR(VLOOKUP(AN$2,$B3:$AB3,27,FALSE),0) -> 2 | AO3: =IF(SUM(AG3:AN3) = 5, "Good", "ERROR") -> Good | AP3: =IFERROR(VLOOKUP(AP$2,$A3:$AA3,11,FALSE),0)+IFERROR(VLOOKUP(AP$2,$B3:$AB3,11,FALSE),0) -> 0 | AQ3: =IFERROR(VLOOKUP(AQ$2,$A3:$AA3,11,FALSE),0)+IFERROR(VLOOKUP(AQ$2,$B3:$AB3,11,FALSE),0) -> 0 | AR3: =IFERROR(VLOOKUP(AR$2,$A3:$AA3,11,FALSE),0)+IFERROR(VLOOKUP(AR$2,$B3:$AB3,11,FALSE),0) -> 0 | AS3: =IFERROR(VLOOKUP(AS$2,$A3:$AA3,11,FALSE),0)+IFERROR(VLOOKUP(AS$2,$B3:$AB3,11,FALSE),0) -> 0 | AT3: =IFERROR(VLOOKUP(AT$2,$A3:$AA3,11,FALSE),0)+IFERROR(VLOOKUP(AT$2,$B3:$AB3,11,FALSE),0) -> 0 | AU3: =IFERROR(VLOOKUP(AU$2,$A3:$AA3,11,FALSE),0)+IFERROR(VLOOKUP(AU$2,$B3:$AB3,11,FALSE),0) -> 0 | AV3: =IFERROR(VLOOKUP(AV$2,$A3:$AA3,11,FALSE),0)+IFERROR(VLOOKUP(AV$2,$B3:$AB3,11,FALSE),0) -> 34.2 | AW3: =IFERROR(VLOOKUP(AW$2,$A3:$AA3,11,FALSE),0)+IFERROR(VLOOKUP(AW$2,$B3:$AB3,11,FALSE),0) -> 33.1 | AY3: =IFERROR(VLOOKUP(AY$2,$A3:$AA3,21,FALSE),0)+IFERROR(VLOOKUP(AY$2,$B3:$AB3,21,FALSE),0) -> 0 | AZ3: =IFERROR(VLOOKUP(AZ$2,$A3:$AA3,21,FALSE),0)+IFERROR(VLOOKUP(AZ$2,$B3:$AB3,21,FALSE),0) -> 0 | BA3: =IFERROR(VLOOKUP(BA$2,$A3:$AA3,21,FALSE),0)+IFERROR(VLOOKUP(BA$2,$B3:$AB3,21,FALSE),0) -> 0 | BB3: =IFERROR(VLOOKUP(BB$2,$A3:$AA3,21,FALSE),0)+IFERROR(VLOOKUP(BB$2,$B3:$AB3,21,FALSE),0) -> 0 | BC3: =IFERROR(VLOOKUP(BC$2,$A3:$AA3,21,FALSE),0)+IFERROR(VLOOKUP(BC$2,$B3:$AB3,21,FALSE),0) -> 0 | BD3: =IFERROR(VLOOKUP(BD$2,$A3:$AA3,21,FALSE),0)+IFERROR(VLOOKUP(BD$2,$B3:$AB3,21,FALSE),0) -> 0 | BE3: =IFERROR(VLOOKUP(BE$2,$A3:$AA3,21,FALSE),0)+IFERROR(VLOOKUP(BE$2,$B3:$AB3,21,FALSE),0) -> 1.315 | BF3: =IFERROR(VLOOKUP(BF$2,$A3:$AA3,21,FALSE),0)+IFERROR(VLOOKUP(BF$2,$B3:$AB3,21,FALSE),0) -> 1.35 | BH3: =IFERROR(VLOOKUP(BH$2,$A3:$AA3,23,FALSE),0)+IFERROR(VLOOKUP(BH$2,$B3:$AB3,23,FALSE),0) -> 0 | BI3: =IFERROR(VLOOKUP(BI$2,$A3:$AA3,23,FALSE),0)+IFERROR(VLOOKUP(BI$2,$B3:$AB3,23,FALSE),0) -> 0 | BJ3: =IFERROR(VLOOKUP(BJ$2,$A3:$AA3,23,FALSE),0)+IFERROR(VLOOKUP(BJ$2,$B3:$AB3,23,FALSE),0) -> 0 | BK3: =IFERROR(VLOOKUP(BK$2,$A3:$AA3,23,FALSE),0)+IFERROR(VLOOKUP(BK$2,$B3:$AB3,23,FALSE),0) -> 0 | BL3: =IFERROR(VLOOKUP(BL$2,$A3:$AA3,23,FALSE),0)+IFERROR(VLOOKUP(BL$2,$B3:$AB3,23,FALSE),0) -> 0 | BM3: =IFERROR(VLOOKUP(BM$2,$A3:$AA3,23,FALSE),0)+IFERROR(VLOOKUP(BM$2,$B3:$AB3,23,FALSE),0) -> 0 | BN3: =IFERROR(VLOOKUP(BN$2,$A3:$AA3,23,FALSE),0)+IFERROR(VLOOKUP(BN$2,$B3:$AB3,23,FALSE),0) -> 23.42 | BO3: =IFERROR(VLOOKUP(BO$2,$A3:$AA3,23,FALSE),0)+IFERROR(VLOOKUP(BO$2,$B3:$AB3,23,FALSE),0) -> 23.76
A4: Tayven/Tony | B4: Mark/Neil | C4: 36.08 | D4: 39.55 | E4: 0 | F4: 1 | G4: 35.46 | H4: 36.66 | I4: 0 | J4: 1 | K4: =(C4+G4)/2 -> 35.77 | L4: =(D4+H4)/2 -> 38.105 | M4: 0.96 | N4: 1.09 | O4: 0 | P4: 1 | Q4: 1.04 | R4: 1.04 | S4: 1 | T4: 0 | U4: =(M4+Q4)/2 -> 1 | V4: =(N4+R4)/2 -> 1.065 | W4: 22.68 | X4: 27.76 | Y4: 0 | Z4: 1 | AA4: =E4+O4+Y4+S4+I4 -> 1 | AB4: =F4+P4+Z4+J4+T4 -> 4 | AD4: =IF(AA4+AB4 = 5, "Good", "ERROR") -> Good | AG4: =IFERROR(VLOOKUP(AG$2,$A4:$AA4,27,FALSE),0)+IFERROR(VLOOKUP(AG$2,$B4:$AB4,27,FALSE),0) -> 0 | AH4: =IFERROR(VLOOKUP(AH$2,$A4:$AA4,27,FALSE),0)+IFERROR(VLOOKUP(AH$2,$B4:$AB4,27,FALSE),0) -> 0 | AI4: =IFERROR(VLOOKUP(AI$2,$A4:$AA4,27,FALSE),0)+IFERROR(VLOOKUP(AI$2,$B4:$AB4,27,FALSE),0) -> 0 | AJ4: =IFERROR(VLOOKUP(AJ$2,$A4:$AA4,27,FALSE),0)+IFERROR(VLOOKUP(AJ$2,$B4:$AB4,27,FALSE),0) -> 0 | AK4: =IFERROR(VLOOKUP(AK$2,$A4:$AA4,27,FALSE),0)+IFERROR(VLOOKUP(AK$2,$B4:$AB4,27,FALSE),0) -> 4 | AL4: =IFERROR(VLOOKUP(AL$2,$A4:$AA4,27,FALSE),0)+IFERROR(VLOOKUP(AL$2,$B4:$AB4,27,FALSE),0) -> 1 | AM4: =IFERROR(VLOOKUP(AM$2,$A4:$AA4,27,FALSE),0)+IFERROR(VLOOKUP(AM$2,$B4:$AB4,27,FALSE),0) -> 0 | AN4: =IFERROR(VLOOKUP(AN$2,$A4:$AA4,27,FALSE),0)+IFERROR(VLOOKUP(AN$2,$B4:$AB4,27,FALSE),0) -> 0 | AO4: =IF(SUM(AG4:AN4) = 5, "Good", "ERROR") -> Good | AP4: =IFERROR(VLOOKUP(AP$2,$A4:$AA4,11,FALSE),0)+IFERROR(VLOOKUP(AP$2,$B4:$AB4,11,FALSE),0) -> 0 | AQ4: =IFERROR(VLOOKUP(AQ$2,$A4:$AA4,11,FALSE),0)+IFERROR(VLOOKUP(AQ$2,$B4:$AB4,11,FALSE),0) -> 0 | AR4: =IFERROR(VLOOKUP(AR$2,$A4:$AA4,11,FALSE),0)+IFERROR(VLOOKUP(AR$2,$B4:$AB4,11,FALSE),0) -> 0 | AS4: =IFERROR(VLOOKUP(AS$2,$A4:$AA4,11,FALSE),0)+IFERROR(VLOOKUP(AS$2,$B4:$AB4,11,FALSE),0) -> 0 | AT4: =IFERROR(VLOOKUP(AT$2,$A4:$AA4,11,FALSE),0)+IFERROR(VLOOKUP(AT$2,$B4:$AB4,11,FALSE),0) -> 38.105 | AU4: =IFERROR(VLOOKUP(AU$2,$A4:$AA4,11,FALSE),0)+IFERROR(VLOOKUP(AU$2,$B4:$AB4,11,FALSE),0) -> 35.77 | AV4: =IFERROR(VLOOKUP(AV$2,$A4:$AA4,11,FALSE),0)+IFERROR(VLOOKUP(AV$2,$B4:$AB4,11,FALSE),0) -> 0 | AW4: =IFERROR(VLOOKUP(AW$2,$A4:$AA4,11,FALSE),0)+IFERROR(VLOOKUP(AW$2,$B4:$AB4,11,FALSE),0) -> 0 | AY4: =IFERROR(VLOOKUP(AY$2,$A4:$AA4,21,FALSE),0)+IFERROR(VLOOKUP(AY$2,$B4:$AB4,21,FALSE),0) -> 0 | AZ4: =IFERROR(VLOOKUP(AZ$2,$A4:$AA4,21,FALSE),0)+IFERROR(VLOOKUP(AZ$2,$B4:$AB4,21,FALSE),0) -> 0 | BA4: =IFERROR(VLOOKUP(BA$2,$A4:$AA4,21,FALSE),0)+IFERROR(VLOOKUP(BA$2,$B4:$AB4,21,FALSE),0) -> 0 | BB4: =IFERROR(VLOOKUP(BB$2,$A4:$AA4,21,FALSE),0)+IFERROR(VLOOKUP(BB$2,$B4:$AB4,21,FALSE),0) -> 0 | BC4: =IFERROR(VLOOKUP(BC$2,$A4:$AA4,21,FALSE),0)+IFERROR(VLOOKUP(BC$2,$B4:$AB4,21,FALSE),0) -> 1.065 | BD4: =IFERROR(VLOOKUP(BD$2,$A4:$AA4,21,FALSE),0)+IFERROR(VLOOKUP(BD$2,$B4:$AB4,21,FALSE),0) -> 1 | BE4: =IFERROR(VLOOKUP(BE$2,$A4:$AA4,21,FALSE),0)+IFERROR(VLOOKUP(BE$2,$B4:$AB4,21,FALSE),0) -> 0 | BF4: =IFERROR(VLOOKUP(BF$2,$A4:$AA4,21,FALSE),0)+IFERROR(VLOOKUP(BF$2,$B4:$AB4,21,FALSE),0) -> 0 | BH4: =IFERROR(VLOOKUP(BH$2,$A4:$AA4,23,FALSE),0)+IFERROR(VLOOKUP(BH$2,$B4:$AB4,23,FALSE),0) -> 0 | BI4: =IFERROR(VLOOKUP(BI$2,$A4:$AA4,23,FALSE),0)+IFERROR(VLOOKUP(BI$2,$B4:$AB4,23,FALSE),0) -> 0 | BJ4: =IFERROR(VLOOKUP(BJ$2,$A4:$AA4,23,FALSE),0)+IFERROR(VLOOKUP(BJ$2,$B4:$AB4,23,FALSE),0) -> 0 | BK4: =IFERROR(VLOOKUP(BK$2,$A4:$AA4,23,FALSE),0)+IFERROR(VLOOKUP(BK$2,$B4:$AB4,23,FALSE),0) -> 0 | BL4: =IFERROR(VLOOKUP(BL$2,$A4:$AA4,23,FALSE),0)+IFERROR(VLOOKUP(BL$2,$B4:$AB4,23,FALSE),0) -> 27.76 | BM4: =IFERROR(VLOOKUP(BM$2,$A4:$AA4,23,FALSE),0)+IFERROR(VLOOKUP(BM$2,$B4:$AB4,23,FALSE),0) -> 22.68 | BN4: =IFERROR(VLOOKUP(BN$2,$A4:$AA4,23,FALSE),0)+IFERROR(VLOOKUP(BN$2,$B4:$AB4,23,FALSE),0) -> 0 | BO4: =IFERROR(VLOOKUP(BO$2,$A4:$AA4,23,FALSE),0)+IFERROR(VLOOKUP(BO$2,$B4:$AB4,23,FALSE),0) -> 0
A5: Clarence/Mike H | B5: Todd/Mike C | C5: 40.62 | D5: 40.83 | E5: 1 | F5: 0 | G5: 32.5 | H5: 39.55 | I5: 0 | J5: 1 | K5: =(C5+G5)/2 -> 36.56 | L5: =(D5+H5)/2 -> 40.19 | M5: 0.98 | N5: 0.69 | O5: 1 | P5: 0 | Q5: 1.24 | R5: 1.33 | S5: 0 | T5: 1 | U5: =(M5+Q5)/2 -> 1.11 | V5: =(N5+R5)/2 -> 1.01 | W5: 22.77 | X5: 23.76 | Y5: 0 | Z5: 1 | AA5: =E5+O5+Y5+S5+I5 -> 2 | AB5: =F5+P5+Z5+J5+T5 -> 3 | AD5: =IF(AA5+AB5 = 5, "Good", "ERROR") -> Good | AG5: =IFERROR(VLOOKUP(AG$2,$A5:$AA5,27,FALSE),0)+IFERROR(VLOOKUP(AG$2,$B5:$AB5,27,FALSE),0) -> 3 | AH5: =IFERROR(VLOOKUP(AH$2,$A5:$AA5,27,FALSE),0)+IFERROR(VLOOKUP(AH$2,$B5:$AB5,27,FALSE),0) -> 2 | AI5: =IFERROR(VLOOKUP(AI$2,$A5:$AA5,27,FALSE),0)+IFERROR(VLOOKUP(AI$2,$B5:$AB5,27,FALSE),0) -> 0 | AJ5: =IFERROR(VLOOKUP(AJ$2,$A5:$AA5,27,FALSE),0)+IFERROR(VLOOKUP(AJ$2,$B5:$AB5,27,FALSE),0) -> 0 | AK5: =IFERROR(VLOOKUP(AK$2,$A5:$AA5,27,FALSE),0)+IFERROR(VLOOKUP(AK$2,$B5:$AB5,27,FALSE),0) -> 0 | AL5: =IFERROR(VLOOKUP(AL$2,$A5:$AA5,27,FALSE),0)+IFERROR(VLOOKUP(AL$2,$B5:$AB5,27,FALSE),0) -> 0 | AM5: =IFERROR(VLOOKUP(AM$2,$A5:$AA5,27,FALSE),0)+IFERROR(VLOOKUP(AM$2,$B5:$AB5,27,FALSE),0) -> 0 | AN5: =IFERROR(VLOOKUP(AN$2,$A5:$AA5,27,FALSE),0)+IFERROR(VLOOKUP(AN$2,$B5:$AB5,27,FALSE),0) -> 0 | AO5: =IF(SUM(AG5:AN5) = 5, "Good", "ERROR") -> Good | AP5: =IFERROR(VLOOKUP(AP$2,$A5:$AA5,11,FALSE),0)+IFERROR(VLOOKUP(AP$2,$B5:$AB5,11,FALSE),0) -> 40.19 | AQ5: =IFERROR(VLOOKUP(AQ$2,$A5:$AA5,11,FALSE),0)+IFERROR(VLOOKUP(AQ$2,$B5:$AB5,11,FALSE),0) -> 36.56 | AR5: =IFERROR(VLOOKUP(AR$2,$A5:$AA5,11,FALSE),0)+IFERROR(VLOOKUP(AR$2,$B5:$AB5,11,FALSE),0) -> 0 | AS5: =IFERROR(VLOOKUP(AS$2,$A5:$AA5,11,FALSE),0)+IFERROR(VLOOKUP(AS$2,$B5:$AB5,11,FALSE),0) -> 0 | AT5: =IFERROR(VLOOKUP(AT$2,$A5:$AA5,11,FALSE),0)+IFERROR(VLOOKUP(AT$2,$B5:$AB5,11,FALSE),0) -> 0 | AU5: =IFERROR(VLOOKUP(AU$2,$A5:$AA5,11,FALSE),0)+IFERROR(VLOOKUP(AU$2,$B5:$AB5,11,FALSE),0) -> 0 | AV5: =IFERROR(VLOOKUP(AV$2,$A5:$AA5,11,FALSE),0)+IFERROR(VLOOKUP(AV$2,$B5:$AB5,11,FALSE),0) -> 0 | AW5: =IFERROR(VLOOKUP(AW$2,$A5:$AA5,11,FALSE),0)+IFERROR(VLOOKUP(AW$2,$B5:$AB5,11,FALSE),0) -> 0 | AY5: =IFERROR(VLOOKUP(AY$2,$A5:$AA5,21,FALSE),0)+IFERROR(VLOOKUP(AY$2,$B5:$AB5,21,FALSE),0) -> 1.01 | AZ5: =IFERROR(VLOOKUP(AZ$2,$A5:$AA5,21,FALSE),0)+IFERROR(VLOOKUP(AZ$2,$B5:$AB5,21,FALSE),0) -> 1.11 | BA5: =IFERROR(VLOOKUP(BA$2,$A5:$AA5,21,FALSE),0)+IFERROR(VLOOKUP(BA$2,$B5:$AB5,21,FALSE),0) -> 0 | BB5: =IFERROR(VLOOKUP(BB$2,$A5:$AA5,21,FALSE),0)+IFERROR(VLOOKUP(BB$2,$B5:$AB5,21,FALSE),0) -> 0 | BC5: =IFERROR(VLOOKUP(BC$2,$A5:$AA5,21,FALSE),0)+IFERROR(VLOOKUP(BC$2,$B5:$AB5,21,FALSE),0) -> 0 | BD5: =IFERROR(VLOOKUP(BD$2,$A5:$AA5,21,FALSE),0)+IFERROR(VLOOKUP(BD$2,$B5:$AB5,21,FALSE),0) -> 0 | BE5: =IFERROR(VLOOKUP(BE$2,$A5:$AA5,21,FALSE),0)+IFERROR(VLOOKUP(BE$2,$B5:$AB5,21,FALSE),0) -> 0 | BF5: =IFERROR(VLOOKUP(BF$2,$A5:$AA5,21,FALSE),0)+IFERROR(VLOOKUP(BF$2,$B5:$AB5,21,FALSE),0) -> 0 | BH5: =IFERROR(VLOOKUP(BH$2,$A5:$AA5,23,FALSE),0)+IFERROR(VLOOKUP(BH$2,$B5:$AB5,23,FALSE),0) -> 23.76 | BI5: =IFERROR(VLOOKUP(BI$2,$A5:$AA5,23,FALSE),0)+IFERROR(VLOOKUP(BI$2,$B5:$AB5,23,FALSE),0) -> 22.77 | BJ5: =IFERROR(VLOOKUP(BJ$2,$A5:$AA5,23,FALSE),0)+IFERROR(VLOOKUP(BJ$2,$B5:$AB5,23,FALSE),0) -> 0 | BK5: =IFERROR(VLOOKUP(BK$2,$A5:$AA5,23,FALSE),0)+IFERROR(VLOOKUP(BK$2,$B5:$AB5,23,FALSE),0) -> 0 | BL5: =IFERROR(VLOOKUP(BL$2,$A5:$AA5,23,FALSE),0)+IFERROR(VLOOKUP(BL$2,$B5:$AB5,23,FALSE),0) -> 0 | BM5: =IFERROR(VLOOKUP(BM$2,$A5:$AA5,23,FALSE),0)+IFERROR(VLOOKUP(BM$2,$B5:$AB5,23,FALSE),0) -> 0 | BN5: =IFERROR(VLOOKUP(BN$2,$A5:$AA5,23,FALSE),0)+IFERROR(VLOOKUP(BN$2,$B5:$AB5,23,FALSE),0) -> 0 | BO5: =IFERROR(VLOOKUP(BO$2,$A5:$AA5,23,FALSE),0)+IFERROR(VLOOKUP(BO$2,$B5:$AB5,23,FALSE),0) -> 0
A6: Kevin/Paul | B6: Jason/Mike A | C6: 32.7 | D6: 31.8 | E6: 1 | F6: 0 | G6: 39.1 | H6: 39.1 | I6: 0 | J6: 1 | K6: =(C6+G6)/2 -> 35.9 | L6: =(D6+H6)/2 -> 35.45 | M6: 1.3 | N6: 1.3 | O6: 0 | P6: 1 | Q6: 1.5 | R6: 1.5 | S6: 1 | T6: 0 | U6: =(M6+Q6)/2 -> 1.4 | V6: =(N6+R6)/2 -> 1.4 | W6: 11 | X6: 10.8 | Y6: 0 | Z6: 1 | AA6: =E6+O6+Y6+S6+I6 -> 2 | AB6: =F6+P6+Z6+J6+T6 -> 3 | AD6: =IF(AA6+AB6 = 5, "Good", "ERROR") -> Good | AG6: =IFERROR(VLOOKUP(AG$2,$A6:$AA6,27,FALSE),0)+IFERROR(VLOOKUP(AG$2,$B6:$AB6,27,FALSE),0) -> 0 | AH6: =IFERROR(VLOOKUP(AH$2,$A6:$AA6,27,FALSE),0)+IFERROR(VLOOKUP(AH$2,$B6:$AB6,27,FALSE),0) -> 0 | AI6: =IFERROR(VLOOKUP(AI$2,$A6:$AA6,27,FALSE),0)+IFERROR(VLOOKUP(AI$2,$B6:$AB6,27,FALSE),0) -> 3 | AJ6: =IFERROR(VLOOKUP(AJ$2,$A6:$AA6,27,FALSE),0)+IFERROR(VLOOKUP(AJ$2,$B6:$AB6,27,FALSE),0) -> 2 | AK6: =IFERROR(VLOOKUP(AK$2,$A6:$AA6,27,FALSE),0)+IFERROR(VLOOKUP(AK$2,$B6:$AB6,27,FALSE),0) -> 0 | AL6: =IFERROR(VLOOKUP(AL$2,$A6:$AA6,27,FALSE),0)+IFERROR(VLOOKUP(AL$2,$B6:$AB6,27,FALSE),0) -> 0 | AM6: =IFERROR(VLOOKUP(AM$2,$A6:$AA6,27,FALSE),0)+IFERROR(VLOOKUP(AM$2,$B6:$AB6,27,FALSE),0) -> 0 | AN6: =IFERROR(VLOOKUP(AN$2,$A6:$AA6,27,FALSE),0)+IFERROR(VLOOKUP(AN$2,$B6:$AB6,27,FALSE),0) -> 0 | AO6: =IF(SUM(AG6:AN6) = 5, "Good", "ERROR") -> Good | AP6: =IFERROR(VLOOKUP(AP$2,$A6:$AA6,11,FALSE),0)+IFERROR(VLOOKUP(AP$2,$B6:$AB6,11,FALSE),0) -> 0 | AQ6: =IFERROR(VLOOKUP(AQ$2,$A6:$AA6,11,FALSE),0)+IFERROR(VLOOKUP(AQ$2,$B6:$AB6,11,FALSE),0) -> 0 | AR6: =IFERROR(VLOOKUP(AR$2,$A6:$AA6,11,FALSE),0)+IFERROR(VLOOKUP(AR$2,$B6:$AB6,11,FALSE),0) -> 35.45 | AS6: =IFERROR(VLOOKUP(AS$2,$A6:$AA6,11,FALSE),0)+IFERROR(VLOOKUP(AS$2,$B6:$AB6,11,FALSE),0) -> 35.9 | AT6: =IFERROR(VLOOKUP(AT$2,$A6:$AA6,11,FALSE),0)+IFERROR(VLOOKUP(AT$2,$B6:$AB6,11,FALSE),0) -> 0 | AU6: =IFERROR(VLOOKUP(AU$2,$A6:$AA6,11,FALSE),0)+IFERROR(VLOOKUP(AU$2,$B6:$AB6,11,FALSE),0) -> 0 | AV6: =IFERROR(VLOOKUP(AV$2,$A6:$AA6,11,FALSE),0)+IFERROR(VLOOKUP(AV$2,$B6:$AB6,11,FALSE),0) -> 0 | AW6: =IFERROR(VLOOKUP(AW$2,$A6:$AA6,11,FALSE),0)+IFERROR(VLOOKUP(AW$2,$B6:$AB6,11,FALSE),0) -> 0 | AY6: =IFERROR(VLOOKUP(AY$2,$A6:$AA6,21,FALSE),0)+IFERROR(VLOOKUP(AY$2,$B6:$AB6,21,FALSE),0) -> 0 | AZ6: =IFERROR(VLOOKUP(AZ$2,$A6:$AA6,21,FALSE),0)+IFERROR(VLOOKUP(AZ$2,$B6:$AB6,21,FALSE),0) -> 0 | BA6: =IFERROR(VLOOKUP(BA$2,$A6:$AA6,21,FALSE),0)+IFERROR(VLOOKUP(BA$2,$B6:$AB6,21,FALSE),0) -> 1.4 | BB6: =IFERROR(VLOOKUP(BB$2,$A6:$AA6,21,FALSE),0)+IFERROR(VLOOKUP(BB$2,$B6:$AB6,21,FALSE),0) -> 1.4 | BC6: =IFERROR(VLOOKUP(BC$2,$A6:$AA6,21,FALSE),0)+IFERROR(VLOOKUP(BC$2,$B6:$AB6,21,FALSE),0) -> 0 | BD6: =IFERROR(VLOOKUP(BD$2,$A6:$AA6,21,FALSE),0)+IFERROR(VLOOKUP(BD$2,$B6:$AB6,21,FALSE),0) -> 0 | BE6: =IFERROR(VLOOKUP(BE$2,$A6:$AA6,21,FALSE),0)+IFERROR(VLOOKUP(BE$2,$B6:$AB6,21,FALSE),0) -> 0 | BF6: =IFERROR(VLOOKUP(BF$2,$A6:$AA6,21,FALSE),0)+IFERROR(VLOOKUP(BF$2,$B6:$AB6,21,FALSE),0) -> 0 | BH6: =IFERROR(VLOOKUP(BH$2,$A6:$AA6,23,FALSE),0)+IFERROR(VLOOKUP(BH$2,$B6:$AB6,23,FALSE),0) -> 0 | BI6: =IFERROR(VLOOKUP(BI$2,$A6:$AA6,23,FALSE),0)+IFERROR(VLOOKUP(BI$2,$B6:$AB6,23,FALSE),0) -> 0 | BJ6: =IFERROR(VLOOKUP(BJ$2,$A6:$AA6,23,FALSE),0)+IFERROR(VLOOKUP(BJ$2,$B6:$AB6,23,FALSE),0) -> 10.8 | BK6: =IFERROR(VLOOKUP(BK$2,$A6:$AA6,23,FALSE),0)+IFERROR(VLOOKUP(BK$2,$B6:$AB6,23,FALSE),0) -> 11 | BL6: =IFERROR(VLOOKUP(BL$2,$A6:$AA6,23,FALSE),0)+IFERROR(VLOOKUP(BL$2,$B6:$AB6,23,FALSE),0) -> 0 | BM6: =IFERROR(VLOOKUP(BM$2,$A6:$AA6,23,FALSE),0)+IFERROR(VLOOKUP(BM$2,$B6:$AB6,23,FALSE),0) -> 0 | BN6: =IFERROR(VLOOKUP(BN$2,$A6:$AA6,23,FALSE),0)+IFERROR(VLOOKUP(BN$2,$B6:$AB6,23,FALSE),0) -> 0 | BO6: =IFERROR(VLOOKUP(BO$2,$A6:$AA6,23,FALSE),0)+IFERROR(VLOOKUP(BO$2,$B6:$AB6,23,FALSE),0) -> 0
A7: Jason/Mike A | B7: Todd/Mike C | C7: 39.55 | D7: 36.23 | E7: 1 | F7: 0 | G7: 20.04 | H7: 20.79 | I7: 1 | J7: 0 | K7: =(C7+G7)/2 -> 29.795 | L7: =(D7+H7)/2 -> 28.51 | M7: 0.93 | N7: 0.88 | O7: 1 | P7: 0 | Q7: 1.12 | R7: 1.76 | S7: 0 | T7: 1 | U7: =(M7+Q7)/2 -> 1.025 | V7: =(N7+R7)/2 -> 1.32 | W7: 39.26 | X7: 39.86 | Y7: 1 | Z7: 0 | AA7: =E7+O7+Y7+S7+I7 -> 4 | AB7: =F7+P7+Z7+J7+T7 -> 1 | AD7: =IF(AA7+AB7 = 5, "Good", "ERROR") -> Good | AG7: =IFERROR(VLOOKUP(AG$2,$A7:$AA7,27,FALSE),0)+IFERROR(VLOOKUP(AG$2,$B7:$AB7,27,FALSE),0) -> 1 | AH7: =IFERROR(VLOOKUP(AH$2,$A7:$AA7,27,FALSE),0)+IFERROR(VLOOKUP(AH$2,$B7:$AB7,27,FALSE),0) -> 0 | AI7: =IFERROR(VLOOKUP(AI$2,$A7:$AA7,27,FALSE),0)+IFERROR(VLOOKUP(AI$2,$B7:$AB7,27,FALSE),0) -> 4 | AJ7: =IFERROR(VLOOKUP(AJ$2,$A7:$AA7,27,FALSE),0)+IFERROR(VLOOKUP(AJ$2,$B7:$AB7,27,FALSE),0) -> 0 | AK7: =IFERROR(VLOOKUP(AK$2,$A7:$AA7,27,FALSE),0)+IFERROR(VLOOKUP(AK$2,$B7:$AB7,27,FALSE),0) -> 0 | AL7: =IFERROR(VLOOKUP(AL$2,$A7:$AA7,27,FALSE),0)+IFERROR(VLOOKUP(AL$2,$B7:$AB7,27,FALSE),0) -> 0 | AM7: =IFERROR(VLOOKUP(AM$2,$A7:$AA7,27,FALSE),0)+IFERROR(VLOOKUP(AM$2,$B7:$AB7,27,FALSE),0) -> 0 | AN7: =IFERROR(VLOOKUP(AN$2,$A7:$AA7,27,FALSE),0)+IFERROR(VLOOKUP(AN$2,$B7:$AB7,27,FALSE),0) -> 0 | AO7: =IF(SUM(AG7:AN7) = 5, "Good", "ERROR") -> Good | AP7: =IFERROR(VLOOKUP(AP$2,$A7:$AA7,11,FALSE),0)+IFERROR(VLOOKUP(AP$2,$B7:$AB7,11,FALSE),0) -> 28.51 | AQ7: =IFERROR(VLOOKUP(AQ$2,$A7:$AA7,11,FALSE),0)+IFERROR(VLOOKUP(AQ$2,$B7:$AB7,11,FALSE),0) -> 0 | AR7: =IFERROR(VLOOKUP(AR$2,$A7:$AA7,11,FALSE),0)+IFERROR(VLOOKUP(AR$2,$B7:$AB7,11,FALSE),0) -> 29.795 | AS7: =IFERROR(VLOOKUP(AS$2,$A7:$AA7,11,FALSE),0)+IFERROR(VLOOKUP(AS$2,$B7:$AB7,11,FALSE),0) -> 0 | AT7: =IFERROR(VLOOKUP(AT$2,$A7:$AA7,11,FALSE),0)+IFERROR(VLOOKUP(AT$2,$B7:$AB7,11,FALSE),0) -> 0 | AU7: =IFERROR(VLOOKUP(AU$2,$A7:$AA7,11,FALSE),0)+IFERROR(VLOOKUP(AU$2,$B7:$AB7,11,FALSE),0) -> 0 | AV7: =IFERROR(VLOOKUP(AV$2,$A7:$AA7,11,FALSE),0)+IFERROR(VLOOKUP(AV$2,$B7:$AB7,11,FALSE),0) -> 0 | AW7: =IFERROR(VLOOKUP(AW$2,$A7:$AA7,11,FALSE),0)+IFERROR(VLOOKUP(AW$2,$B7:$AB7,11,FALSE),0) -> 0 | AY7: =IFERROR(VLOOKUP(AY$2,$A7:$AA7,21,FALSE),0)+IFERROR(VLOOKUP(AY$2,$B7:$AB7,21,FALSE),0) -> 1.32 | AZ7: =IFERROR(VLOOKUP(AZ$2,$A7:$AA7,21,FALSE),0)+IFERROR(VLOOKUP(AZ$2,$B7:$AB7,21,FALSE),0) -> 0 | BA7: =IFERROR(VLOOKUP(BA$2,$A7:$AA7,21,FALSE),0)+IFERROR(VLOOKUP(BA$2,$B7:$AB7,21,FALSE),0) -> 1.025 | BB7: =IFERROR(VLOOKUP(BB$2,$A7:$AA7,21,FALSE),0)+IFERROR(VLOOKUP(BB$2,$B7:$AB7,21,FALSE),0) -> 0 | BC7: =IFERROR(VLOOKUP(BC$2,$A7:$AA7,21,FALSE),0)+IFERROR(VLOOKUP(BC$2,$B7:$AB7,21,FALSE),0) -> 0 | BD7: =IFERROR(VLOOKUP(BD$2,$A7:$AA7,21,FALSE),0)+IFERROR(VLOOKUP(BD$2,$B7:$AB7,21,FALSE),0) -> 0 | BE7: =IFERROR(VLOOKUP(BE$2,$A7:$AA7,21,FALSE),0)+IFERROR(VLOOKUP(BE$2,$B7:$AB7,21,FALSE),0) -> 0 | BF7: =IFERROR(VLOOKUP(BF$2,$A7:$AA7,21,FALSE),0)+IFERROR(VLOOKUP(BF$2,$B7:$AB7,21,FALSE),0) -> 0 | BH7: =IFERROR(VLOOKUP(BH$2,$A7:$AA7,23,FALSE),0)+IFERROR(VLOOKUP(BH$2,$B7:$AB7,23,FALSE),0) -> 39.86 | BI7: =IFERROR(VLOOKUP(BI$2,$A7:$AA7,23,FALSE),0)+IFERROR(VLOOKUP(BI$2,$B7:$AB7,23,FALSE),0) -> 0 | BJ7: =IFERROR(VLOOKUP(BJ$2,$A7:$AA7,23,FALSE),0)+IFERROR(VLOOKUP(BJ$2,$B7:$AB7,23,FALSE),0) -> 39.26 | BK7: =IFERROR(VLOOKUP(BK$2,$A7:$AA7,23,FALSE),0)+IFERROR(VLOOKUP(BK$2,$B7:$AB7,23,FALSE),0) -> 0 | BL7: =IFERROR(VLOOKUP(BL$2,$A7:$AA7,23,FALSE),0)+IFERROR(VLOOKUP(BL$2,$B7:$AB7,23,FALSE),0) -> 0 | BM7: =IFERROR(VLOOKUP(BM$2,$A7:$AA7,23,FALSE),0)+IFERROR(VLOOKUP(BM$2,$B7:$AB7,23,FALSE),0) -> 0 | BN7: =IFERROR(VLOOKUP(BN$2,$A7:$AA7,23,FALSE),0)+IFERROR(VLOOKUP(BN$2,$B7:$AB7,23,FALSE),0) -> 0 | BO7: =IFERROR(VLOOKUP(BO$2,$A7:$AA7,23,FALSE),0)+IFERROR(VLOOKUP(BO$2,$B7:$AB7,23,FALSE),0) -> 0
A8: Kevin/Paul | B8: Clarence/Mike H | C8: 34.6 | D8: 33.4 | E8: 0 | F8: 1 | G8: 47 | H8: 43.3 | I8: 1 | J8: 0 | K8: =(C8+G8)/2 -> 40.8 | L8: =(D8+H8)/2 -> 38.35 | M8: 1.15 | N8: 1.19 | O8: 0 | P8: 1 | Q8: 1.67 | R8: 1.27 | S8: 1 | T8: 0 | U8: =(M8+Q8)/2 -> 1.41 | V8: =(N8+R8)/2 -> 1.23 | W8: 21.8 | X8: 23.8 | Y8: 0 | Z8: 1 | AA8: =E8+O8+Y8+S8+I8 -> 2 | AB8: =F8+P8+Z8+J8+T8 -> 3 | AD8: =IF(AA8+AB8 = 5, "Good", "ERROR") -> Good | AG8: =IFERROR(VLOOKUP(AG$2,$A8:$AA8,27,FALSE),0)+IFERROR(VLOOKUP(AG$2,$B8:$AB8,27,FALSE),0) -> 0 | AH8: =IFERROR(VLOOKUP(AH$2,$A8:$AA8,27,FALSE),0)+IFERROR(VLOOKUP(AH$2,$B8:$AB8,27,FALSE),0) -> 3 | AI8: =IFERROR(VLOOKUP(AI$2,$A8:$AA8,27,FALSE),0)+IFERROR(VLOOKUP(AI$2,$B8:$AB8,27,FALSE),0) -> 0 | AJ8: =IFERROR(VLOOKUP(AJ$2,$A8:$AA8,27,FALSE),0)+IFERROR(VLOOKUP(AJ$2,$B8:$AB8,27,FALSE),0) -> 2 | AK8: =IFERROR(VLOOKUP(AK$2,$A8:$AA8,27,FALSE),0)+IFERROR(VLOOKUP(AK$2,$B8:$AB8,27,FALSE),0) -> 0 | AL8: =IFERROR(VLOOKUP(AL$2,$A8:$AA8,27,FALSE),0)+IFERROR(VLOOKUP(AL$2,$B8:$AB8,27,FALSE),0) -> 0 | AM8: =IFERROR(VLOOKUP(AM$2,$A8:$AA8,27,FALSE),0)+IFERROR(VLOOKUP(AM$2,$B8:$AB8,27,FALSE),0) -> 0 | AN8: =IFERROR(VLOOKUP(AN$2,$A8:$AA8,27,FALSE),0)+IFERROR(VLOOKUP(AN$2,$B8:$AB8,27,FALSE),0) -> 0 | AO8: =IF(SUM(AG8:AN8) = 5, "Good", "ERROR") -> Good | AP8: =IFERROR(VLOOKUP(AP$2,$A8:$AA8,11,FALSE),0)+IFERROR(VLOOKUP(AP$2,$B8:$AB8,11,FALSE),0) -> 0 | AQ8: =IFERROR(VLOOKUP(AQ$2,$A8:$AA8,11,FALSE),0)+IFERROR(VLOOKUP(AQ$2,$B8:$AB8,11,FALSE),0) -> 38.35 | AR8: =IFERROR(VLOOKUP(AR$2,$A8:$AA8,11,FALSE),0)+IFERROR(VLOOKUP(AR$2,$B8:$AB8,11,FALSE),0) -> 0 | AS8: =IFERROR(VLOOKUP(AS$2,$A8:$AA8,11,FALSE),0)+IFERROR(VLOOKUP(AS$2,$B8:$AB8,11,FALSE),0) -> 40.8 | AT8: =IFERROR(VLOOKUP(AT$2,$A8:$AA8,11,FALSE),0)+IFERROR(VLOOKUP(AT$2,$B8:$AB8,11,FALSE),0) -> 0 | AU8: =IFERROR(VLOOKUP(AU$2,$A8:$AA8,11,FALSE),0)+IFERROR(VLOOKUP(AU$2,$B8:$AB8,11,FALSE),0) -> 0 | AV8: =IFERROR(VLOOKUP(AV$2,$A8:$AA8,11,FALSE),0)+IFERROR(VLOOKUP(AV$2,$B8:$AB8,11,FALSE),0) -> 0 | AW8: =IFERROR(VLOOKUP(AW$2,$A8:$AA8,11,FALSE),0)+IFERROR(VLOOKUP(AW$2,$B8:$AB8,11,FALSE),0) -> 0 | AY8: =IFERROR(VLOOKUP(AY$2,$A8:$AA8,21,FALSE),0)+IFERROR(VLOOKUP(AY$2,$B8:$AB8,21,FALSE),0) -> 0 | AZ8: =IFERROR(VLOOKUP(AZ$2,$A8:$AA8,21,FALSE),0)+IFERROR(VLOOKUP(AZ$2,$B8:$AB8,21,FALSE),0) -> 1.23 | BA8: =IFERROR(VLOOKUP(BA$2,$A8:$AA8,21,FALSE),0)+IFERROR(VLOOKUP(BA$2,$B8:$AB8,21,FALSE),0) -> 0 | BB8: =IFERROR(VLOOKUP(BB$2,$A8:$AA8,21,FALSE),0)+IFERROR(VLOOKUP(BB$2,$B8:$AB8,21,FALSE),0) -> 1.41 | BC8: =IFERROR(VLOOKUP(BC$2,$A8:$AA8,21,FALSE),0)+IFERROR(VLOOKUP(BC$2,$B8:$AB8,21,FALSE),0) -> 0 | BD8: =IFERROR(VLOOKUP(BD$2,$A8:$AA8,21,FALSE),0)+IFERROR(VLOOKUP(BD$2,$B8:$AB8,21,FALSE),0) -> 0 | BE8: =IFERROR(VLOOKUP(BE$2,$A8:$AA8,21,FALSE),0)+IFERROR(VLOOKUP(BE$2,$B8:$AB8,21,FALSE),0) -> 0 | BF8: =IFERROR(VLOOKUP(BF$2,$A8:$AA8,21,FALSE),0)+IFERROR(VLOOKUP(BF$2,$B8:$AB8,21,FALSE),0) -> 0 | BH8: =IFERROR(VLOOKUP(BH$2,$A8:$AA8,23,FALSE),0)+IFERROR(VLOOKUP(BH$2,$B8:$AB8,23,FALSE),0) -> 0 | BI8: =IFERROR(VLOOKUP(BI$2,$A8:$AA8,23,FALSE),0)+IFERROR(VLOOKUP(BI$2,$B8:$AB8,23,FALSE),0) -> 23.8 | BJ8: =IFERROR(VLOOKUP(BJ$2,$A8:$AA8,23,FALSE),0)+IFERROR(VLOOKUP(BJ$2,$B8:$AB8,23,FALSE),0) -> 0 | BK8: =IFERROR(VLOOKUP(BK$2,$A8:$AA8,23,FALSE),0)+IFERROR(VLOOKUP(BK$2,$B8:$AB8,23,FALSE),0) -> 21.8 | BL8: =IFERROR(VLOOKUP(BL$2,$A8:$AA8,23,FALSE),0)+IFERROR(VLOOKUP(BL$2,$B8:$AB8,23,FALSE),0) -> 0 | BM8: =IFERROR(VLOOKUP(BM$2,$A8:$AA8,23,FALSE),0)+IFERROR(VLOOKUP(BM$2,$B8:$AB8,23,FALSE),0) -> 0 | BN8: =IFERROR(VLOOKUP(BN$2,$A8:$AA8,23,FALSE),0)+IFERROR(VLOOKUP(BN$2,$B8:$AB8,23,FALSE),0) -> 0 | BO8: =IFERROR(VLOOKUP(BO$2,$A8:$AA8,23,FALSE),0)+IFERROR(VLOOKUP(BO$2,$B8:$AB8,23,FALSE),0) -> 0
A9: Daniel/David | B9: Tayven/Tony | C9: 41.6 | D9: 46.8 | E9: 0 | F9: 1 | G9: 38.5 | H9: 44.3 | I9: 1 | J9: 0 | K9: =(C9+G9)/2 -> 40.05 | L9: =(D9+H9)/2 -> 45.55 | M9: 1.16 | N9: 1.12 | O9: 1 | P9: 0 | Q9: 1.42 | R9: 1.25 | S9: 1 | T9: 0 | U9: =(M9+Q9)/2 -> 1.29 | V9: =(N9+R9)/2 -> 1.185 | W9: 29.3 | X9: 29.1 | Y9: 0 | Z9: 1 | AA9: =E9+O9+Y9+S9+I9 -> 3 | AB9: =F9+P9+Z9+J9+T9 -> 2 | AD9: =IF(AA9+AB9 = 5, "Good", "ERROR") -> Good | AG9: =IFERROR(VLOOKUP(AG$2,$A9:$AA9,27,FALSE),0)+IFERROR(VLOOKUP(AG$2,$B9:$AB9,27,FALSE),0) -> 0 | AH9: =IFERROR(VLOOKUP(AH$2,$A9:$AA9,27,FALSE),0)+IFERROR(VLOOKUP(AH$2,$B9:$AB9,27,FALSE),0) -> 0 | AI9: =IFERROR(VLOOKUP(AI$2,$A9:$AA9,27,FALSE),0)+IFERROR(VLOOKUP(AI$2,$B9:$AB9,27,FALSE),0) -> 0 | AJ9: =IFERROR(VLOOKUP(AJ$2,$A9:$AA9,27,FALSE),0)+IFERROR(VLOOKUP(AJ$2,$B9:$AB9,27,FALSE),0) -> 0 | AK9: =IFERROR(VLOOKUP(AK$2,$A9:$AA9,27,FALSE),0)+IFERROR(VLOOKUP(AK$2,$B9:$AB9,27,FALSE),0) -> 0 | AL9: =IFERROR(VLOOKUP(AL$2,$A9:$AA9,27,FALSE),0)+IFERROR(VLOOKUP(AL$2,$B9:$AB9,27,FALSE),0) -> 2 | AM9: =IFERROR(VLOOKUP(AM$2,$A9:$AA9,27,FALSE),0)+IFERROR(VLOOKUP(AM$2,$B9:$AB9,27,FALSE),0) -> 0 | AN9: =IFERROR(VLOOKUP(AN$2,$A9:$AA9,27,FALSE),0)+IFERROR(VLOOKUP(AN$2,$B9:$AB9,27,FALSE),0) -> 3 | AO9: =IF(SUM(AG9:AN9) = 5, "Good", "ERROR") -> Good | AP9: =IFERROR(VLOOKUP(AP$2,$A9:$AA9,11,FALSE),0)+IFERROR(VLOOKUP(AP$2,$B9:$AB9,11,FALSE),0) -> 0 | AQ9: =IFERROR(VLOOKUP(AQ$2,$A9:$AA9,11,FALSE),0)+IFERROR(VLOOKUP(AQ$2,$B9:$AB9,11,FALSE),0) -> 0 | AR9: =IFERROR(VLOOKUP(AR$2,$A9:$AA9,11,FALSE),0)+IFERROR(VLOOKUP(AR$2,$B9:$AB9,11,FALSE),0) -> 0 | AS9: =IFERROR(VLOOKUP(AS$2,$A9:$AA9,11,FALSE),0)+IFERROR(VLOOKUP(AS$2,$B9:$AB9,11,FALSE),0) -> 0 | AT9: =IFERROR(VLOOKUP(AT$2,$A9:$AA9,11,FALSE),0)+IFERROR(VLOOKUP(AT$2,$B9:$AB9,11,FALSE),0) -> 0 | AU9: =IFERROR(VLOOKUP(AU$2,$A9:$AA9,11,FALSE),0)+IFERROR(VLOOKUP(AU$2,$B9:$AB9,11,FALSE),0) -> 45.55 | AV9: =IFERROR(VLOOKUP(AV$2,$A9:$AA9,11,FALSE),0)+IFERROR(VLOOKUP(AV$2,$B9:$AB9,11,FALSE),0) -> 0 | AW9: =IFERROR(VLOOKUP(AW$2,$A9:$AA9,11,FALSE),0)+IFERROR(VLOOKUP(AW$2,$B9:$AB9,11,FALSE),0) -> 40.05 | AY9: =IFERROR(VLOOKUP(AY$2,$A9:$AA9,21,FALSE),0)+IFERROR(VLOOKUP(AY$2,$B9:$AB9,21,FALSE),0) -> 0 | AZ9: =IFERROR(VLOOKUP(AZ$2,$A9:$AA9,21,FALSE),0)+IFERROR(VLOOKUP(AZ$2,$B9:$AB9,21,FALSE),0) -> 0 | BA9: =IFERROR(VLOOKUP(BA$2,$A9:$AA9,21,FALSE),0)+IFERROR(VLOOKUP(BA$2,$B9:$AB9,21,FALSE),0) -> 0 | BB9: =IFERROR(VLOOKUP(BB$2,$A9:$AA9,21,FALSE),0)+IFERROR(VLOOKUP(BB$2,$B9:$AB9,21,FALSE),0) -> 0 | BC9: =IFERROR(VLOOKUP(BC$2,$A9:$AA9,21,FALSE),0)+IFERROR(VLOOKUP(BC$2,$B9:$AB9,21,FALSE),0) -> 0 | BD9: =IFERROR(VLOOKUP(BD$2,$A9:$AA9,21,FALSE),0)+IFERROR(VLOOKUP(BD$2,$B9:$AB9,21,FALSE),0) -> 1.185 | BE9: =IFERROR(VLOOKUP(BE$2,$A9:$AA9,21,FALSE),0)+IFERROR(VLOOKUP(BE$2,$B9:$AB9,21,FALSE),0) -> 0 | BF9: =IFERROR(VLOOKUP(BF$2,$A9:$AA9,21,FALSE),0)+IFERROR(VLOOKUP(BF$2,$B9:$AB9,21,FALSE),0) -> 1.29 | BH9: =IFERROR(VLOOKUP(BH$2,$A9:$AA9,23,FALSE),0)+IFERROR(VLOOKUP(BH$2,$B9:$AB9,23,FALSE),0) -> 0 | BI9: =IFERROR(VLOOKUP(BI$2,$A9:$AA9,23,FALSE),0)+IFERROR(VLOOKUP(BI$2,$B9:$AB9,23,FALSE),0) -> 0 | BJ9: =IFERROR(VLOOKUP(BJ$2,$A9:$AA9,23,FALSE),0)+IFERROR(VLOOKUP(BJ$2,$B9:$AB9,23,FALSE),0) -> 0 | BK9: =IFERROR(VLOOKUP(BK$2,$A9:$AA9,23,FALSE),0)+IFERROR(VLOOKUP(BK$2,$B9:$AB9,23,FALSE),0) -> 0 | BL9: =IFERROR(VLOOKUP(BL$2,$A9:$AA9,23,FALSE),0)+IFERROR(VLOOKUP(BL$2,$B9:$AB9,23,FALSE),0) -> 0 | BM9: =IFERROR(VLOOKUP(BM$2,$A9:$AA9,23,FALSE),0)+IFERROR(VLOOKUP(BM$2,$B9:$AB9,23,FALSE),0) -> 29.1 | BN9: =IFERROR(VLOOKUP(BN$2,$A9:$AA9,23,FALSE),0)+IFERROR(VLOOKUP(BN$2,$B9:$AB9,23,FALSE),0) -> 0 | BO9: =IFERROR(VLOOKUP(BO$2,$A9:$AA9,23,FALSE),0)+IFERROR(VLOOKUP(BO$2,$B9:$AB9,23,FALSE),0) -> 29.3
A10: Brian/Olver | B10: Mark/Neil | C10: 32.6 | D10: 37.6 | E10: 0 | F10: 1 | G10: 43.1 | H10: 48.5 | I10: 0 | J10: 1 | K10: =(C10+G10)/2 -> 37.85 | L10: =(D10+H10)/2 -> 43.05 | M10: 1.42 | N10: 1.6 | O10: 0 | P10: 1 | Q10: 0.73 | R10: 0.93 | S10: 0 | T10: 1 | U10: =(M10+Q10)/2 -> 1.075 | V10: =(N10+R10)/2 -> 1.265 | W10: 17.4 | X10: 16.3 | Y10: 1 | Z10: 0 | AA10: =E10+O10+Y10+S10+I10 -> 1 | AB10: =F10+P10+Z10+J10+T10 -> 4 | AD10: =IF(AA10+AB10 = 5, "Good", "ERROR") -> Good | AG10: =IFERROR(VLOOKUP(AG$2,$A10:$AA10,27,FALSE),0)+IFERROR(VLOOKUP(AG$2,$B10:$AB10,27,FALSE),0) -> 0 | AH10: =IFERROR(VLOOKUP(AH$2,$A10:$AA10,27,FALSE),0)+IFERROR(VLOOKUP(AH$2,$B10:$AB10,27,FALSE),0) -> 0 | AI10: =IFERROR(VLOOKUP(AI$2,$A10:$AA10,27,FALSE),0)+IFERROR(VLOOKUP(AI$2,$B10:$AB10,27,FALSE),0) -> 0 | AJ10: =IFERROR(VLOOKUP(AJ$2,$A10:$AA10,27,FALSE),0)+IFERROR(VLOOKUP(AJ$2,$B10:$AB10,27,FALSE),0) -> 0 | AK10: =IFERROR(VLOOKUP(AK$2,$A10:$AA10,27,FALSE),0)+IFERROR(VLOOKUP(AK$2,$B10:$AB10,27,FALSE),0) -> 4 | AL10: =IFERROR(VLOOKUP(AL$2,$A10:$AA10,27,FALSE),0)+IFERROR(VLOOKUP(AL$2,$B10:$AB10,27,FALSE),0) -> 0 | AM10: =IFERROR(VLOOKUP(AM$2,$A10:$AA10,27,FALSE),0)+IFERROR(VLOOKUP(AM$2,$B10:$AB10,27,FALSE),0) -> 1 | AN10: =IFERROR(VLOOKUP(AN$2,$A10:$AA10,27,FALSE),0)+IFERROR(VLOOKUP(AN$2,$B10:$AB10,27,FALSE),0) -> 0 | AO10: =IF(SUM(AG10:AN10) = 5, "Good", "ERROR") -> Good | AP10: =IFERROR(VLOOKUP(AP$2,$A10:$AA10,11,FALSE),0)+IFERROR(VLOOKUP(AP$2,$B10:$AB10,11,FALSE),0) -> 0 | AQ10: =IFERROR(VLOOKUP(AQ$2,$A10:$AA10,11,FALSE),0)+IFERROR(VLOOKUP(AQ$2,$B10:$AB10,11,FALSE),0) -> 0 | AR10: =IFERROR(VLOOKUP(AR$2,$A10:$AA10,11,FALSE),0)+IFERROR(VLOOKUP(AR$2,$B10:$AB10,11,FALSE),0) -> 0 | AS10: =IFERROR(VLOOKUP(AS$2,$A10:$AA10,11,FALSE),0)+IFERROR(VLOOKUP(AS$2,$B10:$AB10,11,FALSE),0) -> 0 | AT10: =IFERROR(VLOOKUP(AT$2,$A10:$AA10,11,FALSE),0)+IFERROR(VLOOKUP(AT$2,$B10:$AB10,11,FALSE),0) -> 43.05 | AU10: =IFERROR(VLOOKUP(AU$2,$A10:$AA10,11,FALSE),0)+IFERROR(VLOOKUP(AU$2,$B10:$AB10,11,FALSE),0) -> 0 | AV10: =IFERROR(VLOOKUP(AV$2,$A10:$AA10,11,FALSE),0)+IFERROR(VLOOKUP(AV$2,$B10:$AB10,11,FALSE),0) -> 37.85 | AW10: =IFERROR(VLOOKUP(AW$2,$A10:$AA10,11,FALSE),0)+IFERROR(VLOOKUP(AW$2,$B10:$AB10,11,FALSE),0) -> 0 | AY10: =IFERROR(VLOOKUP(AY$2,$A10:$AA10,21,FALSE),0)+IFERROR(VLOOKUP(AY$2,$B10:$AB10,21,FALSE),0) -> 0 | AZ10: =IFERROR(VLOOKUP(AZ$2,$A10:$AA10,21,FALSE),0)+IFERROR(VLOOKUP(AZ$2,$B10:$AB10,21,FALSE),0) -> 0 | BA10: =IFERROR(VLOOKUP(BA$2,$A10:$AA10,21,FALSE),0)+IFERROR(VLOOKUP(BA$2,$B10:$AB10,21,FALSE),0) -> 0 | BB10: =IFERROR(VLOOKUP(BB$2,$A10:$AA10,21,FALSE),0)+IFERROR(VLOOKUP(BB$2,$B10:$AB10,21,FALSE),0) -> 0 | BC10: =IFERROR(VLOOKUP(BC$2,$A10:$AA10,21,FALSE),0)+IFERROR(VLOOKUP(BC$2,$B10:$AB10,21,FALSE),0) -> 1.265 | BD10: =IFERROR(VLOOKUP(BD$2,$A10:$AA10,21,FALSE),0)+IFERROR(VLOOKUP(BD$2,$B10:$AB10,21,FALSE),0) -> 0 | BE10: =IFERROR(VLOOKUP(BE$2,$A10:$AA10,21,FALSE),0)+IFERROR(VLOOKUP(BE$2,$B10:$AB10,21,FALSE),0) -> 1.075 | BF10: =IFERROR(VLOOKUP(BF$2,$A10:$AA10,21,FALSE),0)+IFERROR(VLOOKUP(BF$2,$B10:$AB10,21,FALSE),0) -> 0 | BH10: =IFERROR(VLOOKUP(BH$2,$A10:$AA10,23,FALSE),0)+IFERROR(VLOOKUP(BH$2,$B10:$AB10,23,FALSE),0) -> 0 | BI10: =IFERROR(VLOOKUP(BI$2,$A10:$AA10,23,FALSE),0)+IFERROR(VLOOKUP(BI$2,$B10:$AB10,23,FALSE),0) -> 0 | BJ10: =IFERROR(VLOOKUP(BJ$2,$A10:$AA10,23,FALSE),0)+IFERROR(VLOOKUP(BJ$2,$B10:$AB10,23,FALSE),0) -> 0 | BK10: =IFERROR(VLOOKUP(BK$2,$A10:$AA10,23,FALSE),0)+IFERROR(VLOOKUP(BK$2,$B10:$AB10,23,FALSE),0) -> 0 | BL10: =IFERROR(VLOOKUP(BL$2,$A10:$AA10,23,FALSE),0)+IFERROR(VLOOKUP(BL$2,$B10:$AB10,23,FALSE),0) -> 16.3 | BM10: =IFERROR(VLOOKUP(BM$2,$A10:$AA10,23,FALSE),0)+IFERROR(VLOOKUP(BM$2,$B10:$AB10,23,FALSE),0) -> 0 | BN10: =IFERROR(VLOOKUP(BN$2,$A10:$AA10,23,FALSE),0)+IFERROR(VLOOKUP(BN$2,$B10:$AB10,23,FALSE),0) -> 17.4 | BO10: =IFERROR(VLOOKUP(BO$2,$A10:$AA10,23,FALSE),0)+IFERROR(VLOOKUP(BO$2,$B10:$AB10,23,FALSE),0) -> 0
